Workbook
Name fc: 'GROUND&1st'!$AM$2
Name fy: 'GROUND&1st'!$AO$2

Sheet GROUND&1st
B1: Design of Columns for Ground & 1st Floors | AJ1: Design of Columns for Ground & 1st Floor | BJ1: Check Capasity of Columns | CG1: IF COMPRESSION CONTROLS | CZ1: IF TENTION CONTROLS
U2: FOR NON SWAY | AJ2: Col .No | AL2: f'c(Mpa)= | AM2: 28 | AN2: fy(Mpa)= | AO2: 420 | AP2: m= | AQ2: =AO2/(0.85*AM2) -> 17.647059 | AR2: β= | AS2: 0.65 | AT2: φ= | AU2: 0.65 | AW2: østirrups= | AX2: 10 | AY2: Av= | AZ2: =2*PI()*AX2^2/4 -> 157.07963 | BC2: d'(mm)= | BD2: 60 | BE2: φ= | BF2: 0.75 | BH2: fy= | BI2: 280
B3: Column | C3: name | D3: b | E3: h | F3: Lu | G3: Pu | H3: Mu(TOP)x | I3: Mu(BOT)x | J3: Mu(TOP)y | K3: Mu(BOT)y | L3: Check Slinderness X-Dirction | U3: COL.NO | W3: BEAM | Z3: COLUMN | AD3: ψx | AE3: Kx | AL3: b | AM3: h | AN3: d | AO3: Pu | AP3: Mux | AQ3: Muy | AR3: Muox | AS3: Muoy | AT3: Mu eq | AU3: e | AV3: Check | AW3: As | AX3: A's | AY3: ρ | AZ3: Bars | BC3: Shear Design | BJ3: bx=hy | BK3: hx=by | BL3: abx | BM3: aby | BN3: fs'x | BO3: fs'y | BP3: Pbx | BQ3: Pby | BR3: Mbx | BS3: Mby | BT3: ebx | BU3: eby | BV3: ey | BW3: ex | BX3: Check X dirction | BY3: Check Y dirction | BZ3: Pnx | CA3: Pny | CB3: Pno | CC3: Pubiaxial | CD3: Note | CG3: X-direction | CQ3: Y-direction | CZ3: X-direction | DI3: Y-direction
D4: mm | E4: mm | F4: mm | G4: (KN) | H4: (KN.m) | I4: (KN.m) | J4: (KN.m) | K4: (KN.m) | L4: klu/r | M4: 34-12(M1/M2) | N4: CHECK | P4: abs(Mxtop) | Q4: abs(Mxbot) | R4: abs(Mytop) | S4: abs(Mybot) | X4: Beam1x | Y4: Beam2x | Z4: B | AA4: H | AB4: L | AC4: Ix/L | AL4: (mm) | AM4: (mm) | AN4: (mm) | AO4: (Kn) | AP4: (Kn.m) | AQ4: (Kn.m) | AR4: (Kn.m) | AS4: (Kn.m) | AT4: (Kn.m) | AU4: (m) | AW4: (mm^2) | AX4: (mm^2) | BC4: Vu | BD4: Vc | BE4: Vs | BF4: Smax | BG4: Lo | BH4: S | BI4: hoops S→Lo | BJ4: mm | BK4: mm | BL4: mm | BM4: mm | BN4: MPa | BO4: MPa | BP4: KN | BQ4: KN | BR4: KN.m | BS4: KN.m | BT4: m | BU4: m | BV4: (m) | BW4: (m) | BZ4: (Kn) | CA4: (Kn) | CB4: (Kn) | CC4: (Kn) | CG4: As' | CH4: d | CI4: e' | CJ4: A | CK4: B | CL4: C | CM4: D | CN4: a | CO4: Pn | CQ4: d | CR4: e' | CS4: A | CT4: B | CU4: C | CV4: D | CW4: a | CX4: Pn | CZ4: A | DA4: B | DB4: C | DC4: a | DD4: fs' | DE4: C | DF4: a | DG4: Pn | DI4: A | DJ4: B | DK4: C | DL4: a | DM4: fs' | DN4: C | DO4: a | DP4: Pn | DT4: COL | DU4: USE
A5: MIDAH | B5: C2 | D5: 300 | E5: 500 | F5: 1600 | G5: 854.82 | H5: 6.15 | I5: 0 | J5: 0.16 | K5: 0 | L5: =(0.9*F5)/(0.3*E5) -> 9.6 | M5: =IF(P5>Q5,(34-12*I5/H5),(34-12*H5/I5)) -> 34 | N5: =IF(L5<=M5,"sho.col","long.col") -> sho.col | P5: =ABS(H5) -> 6.15 | Q5: =ABS(I5) -> 0 | R5: =ABS(J5) -> 0.16 | S5: =ABS(K5) -> 0 | U5: C1 | V5: Top | W5: B | X5: 0 | Y5: 200 | Z5: 250 | AA5: 500 | AB5: =AB7 -> 1600 | AC5: =(Z5*AA5^3/12)/AB5 -> 1627604.2 | AD5: =(0.7*(AC5+AC7))/(0.35*(X8+Y8)) -> 7.3852539 | AE5: =MIN(MIN(1,(0.7+0.05*(AD5+AD9))),MIN(1,(0.85+0.05*MIN(AD5,AD9)))) -> 0.9 | AI5: 2 , 220 ,152 | AJ5: =B5 -> C2 | AL5: 300 | AM5: 500 | AN5: =AM5-60 -> 440 | AO5: =G5 -> 854.82 | AP5: =P5 -> 6.15 | AQ5: =R5 -> 0.16 | AR5: =AP5+(AQ5*AM5/AL5*((1-AS$2)/AS$2)) -> 6.2935897 | AS5: =AQ5+(AP5*AL5/AM5*((1-AS$2)/AS$2)) -> 2.1469231 | AT5: =MAX(AR5:AS5) -> 6.2935897 | AU5: =AT5/AO5 -> 0.0073624737 | AV5: =IF(AU5<=1,"Compression","Tention") -> Compression | AW5: =IF(MAX(AP5*1000/AO5,AQ5*1000/AO5)>0.1*AM5,IF(IF(AV5="Compression",2*(0.5+AU5*10^3/(AN5-BD$2))*(-AL5*AM$2*AM5/(1.18+3*AU5*10^3*AM5/AN5^2)+AO5*10^3/AU$2)/AO$2,2*AO5*1000*(AU5*1000-0.5*AM5+0.2*AN5)/(AU$2*fy*(AN5-BD$2)))<0.01*AL5*AM5,(0.01*AL5*AM5),IF(AV5="Compression",2*(0.5+AU5*10^3/(AN5-60))*(-AL5*AM$2*AM5/(1.18+3*AU5*10^3*AM5/AN5^2)+AO5*10^3/AU$2)/AO$2,2*AO5*1000*(AU5*1000-0.5*AM5+0.2*AN5)/(AU$2*fy*(AN5-BD$2)))),MAX((AO5*1000/(0.8*AU$2)-0.85*fc*AL5*AM5)/(fy-0.85*fc),0.01*AL5*AM5)) -> 1500 | AX5: =AW5/4 -> 375 | AY5: =AW5/(AL5*AM5) -> 0.01 | AZ5: =EVEN(AW5/(PI()*BB5^2/4)) -> 10 | BA5: φ | BB5: 14 | BC5: 3.07 | BD5: =MIN(fc^0.5*AL5*AN5/(6*1000),fc^0.5*(AL5-60)*AM5/(6*1000)) -> 105.83005 | BE5: =(BC5-BF$2*BD5)/BF$2 -> -101.73672 | BF5: =FLOOR(MIN(AL5/2,MIN((3*AZ$2*BI$2/AM5),(16*AZ$2*BI$2/(fc^0.5*AM5))),(8*BB5),(24*AX$2),300),10) -> 110 | BG5: =MAX(MAX(AL5,AM5),(F5/6),450) -> 500 | BH5: =IF(BC5<0.5*BD5*BF$2,"No Need Shear Reinf.",IF(BC5<=BD5*BF$2,BF5,IF(BE5>4*BD5,"Increase b & d",FLOOR(AZ$2*BI$2*AN5/(BE5*1000),50)))) -> No Need Shear Reinf. | BI5: =IF(BH5="No Need Shear Reinf.","Use Φ"&AX$2&"@"&MIN(BF5,BH5)&"mm",IF(BH5="Increase b & d","Increase b & d","Use Φ"&AX$2&"@"&MIN(BF5,BH5)&"mm")) -> Use Φ10@110mm | BJ5: =AL5 -> 300 | BK5: =AM5 -> 500 | BL5: =0.85*(600*AN5)/(600+fy) -> 220 | BM5: =0.85*(600*(BJ5-60))/(600+fy) -> 120 | BN5: =600*(BL5/0.85-60)*0.85/BL5 -> 460.90909 | BO5: =600*(BM5/0.85-60)*0.85/BM5 -> 345 | BP5: =IF(BN5>fy,(0.85*fc*BL5*BJ5+CG5*(fy-0.85*fc)-CG5*fy),(0.85*fc*BL5*BJ5+CG5*(BN5-0.85*fc)-CG5*fy))/1000 -> 1561.637 | BQ5: =IF(BO5>fy,(0.85*fc*BM5*BK5+CG5*(fy-0.85*fc)-CG5*fy),(0.85*fc*BM5*BK5+CG5*(BO5-0.85*fc)-CG5*fy))/1000 -> 1389.962 | BR5: =IF(BN5>fy,(0.85*fc*BL5*BJ5*(BK5/2-BL5/2)+CG5*(fy-0.85*fc)*(BK5/2-60)+CG5*fy*(BK5/2-60)),(0.85*fc*BL5*BJ5*(AN5-BL5/2-60)+CG5*(BN5-0.85*fc)*(BK5/2-60)+CG5*fy*(BK5/2-60)))/1000000 -> 279.61703 | BS5: =IF(BO5>fy,(0.85*fc*BM5*BK5*((BJ5-60)-BM5/2-60)+CG5*(fy-0.85*AM$2)*(BJ5/2-60)-CG5*fy*(BJ5/2-60)),(0.85*fc*BM5*BK5*((BJ5-60)-BM5/2-60)+CG5*(BO5-0.85*fc)*(BJ5/2-60)-CG5*fy*(BJ5/2-60)))/1000000 -> 167.93658 | BT5: =BR5/BP5 -> 0.17905379 | BU5: =BS5/BQ5 -> 0.12082099 | BV5: =AP5/AO5 -> 0.0071944971 | BW5: =AQ5/AO5 -> 0.00018717391 | BX5: =IF(BT5>BV5,"Compression Controls","Tension Controls") -> Compression Controls | BY5: =IF(BU5>BW5,"Compression Controls","Tension Controls") -> Compression Controls | BZ5: =IF(BX5="Compression Controls",CO5,DG5) -> 3743.9363 | CA5: =IF(BY5="Compression Controls",CX5,DP5) -> 3839.0801 | CB5: =(0.85*fc*BJ5*BK5+CG5*4*(fy-0.85*fc))/1000 -> 4180.148 | CC5: =IF(MAX(AP5*1000/AO5,AQ5*1000/AO5)>0.1*AM5,AU$2/(1/BZ5+1/CA5-1/CB5),AU$2*0.8*CB5) -> 2173.677 | CD5: =IF(CC5>=AO5,"Safe ","Unsafe") -> Safe | CG5: =(AZ5*0.25*22/7*BB5^2)/4 -> 385 | CH5: =BK5-60 -> 440 | CI5: =BV5*1000+BK5/2-60 -> 197.1945 | CJ5: =0.85*fc*BJ5/(2*CI5) -> 18.103953 | CK5: =0.85*fc*BJ5*(1-CH5/CI5) -> -8791.4791 | CL5: =(600*CG5+CG5*(fy-0.85*fc)*(1-(CH5-60)/CI5)) -> 89593.402 | CM5: =-510*CH5*CG5 -> -86394000 | CN5: =(((CK5*CL5/(6*CJ5^2)-(CK5/(3*CJ5))^3-CM5/(2*CJ5))^2+(-(CK5^2/(9*CJ5^2))+CL5/(3*CJ5))^3)^0.5+CK5*CL5/(6*CJ5^2)-CK5^3/(27*CJ5^3)-CM5/(2*CJ5))^(1/3)+(-(((CK5*CL5/(6*CJ5^2)-(CK5/(3*CJ5))^3-CM5/(2*CJ5))^2+(-(CK5^2/(9*CJ5^2))+CL5/(3*CJ5))^3)^0.5)+CK5*CL5/(6*CJ5^2)-CK5^3/(27*CJ5^3)-CM5/(2*CJ5))^(1/3)-CK5/(3*CJ5) -> 495.08443 | CO5: =((0.85*fc*CN5*BJ5)+(CG5*(fy-0.85*fc))-(CG5*600*((0.85*CH5)-CN5)/CN5))/1000 -> 3743.9363 | CQ5: =BJ5-60 -> 240 | CR5: =BW5*1000+BJ5/2-60 -> 90.187174 | CS5: =0.85*fc*BK5/(2*CR5) -> 65.973905 | CT5: =0.85*fc*BK5*(1-CQ5/CR5) -> -19767.474 | CU5: =(600*CG5+CG5*(fy-0.85*fc)*(1-(CQ5-60)/CR5)) -> 79096.149 | CV5: =-510*CQ5*CG5 -> -47124000 | CW5: =(((CT5*CU5/(6*CS5^2)-(CT5/(3*CS5))^3-CV5/(2*CS5))^2+(-(CT5^2/(9*CS5^2))+CU5/(3*CS5))^3)^0.5+CT5*CU5/(6*CS5^2)-CT5^3/(27*CS5^3)-CV5/(2*CS5))^(1/3)+(-(((CT5*CU5/(6*CS5^2)-(CT5/(3*CS5))^3-CV5/(2*CS5))^2+(-(CT5^2/(9*CS5^2))+CU5/(3*CS5))^3)^0.5)+CT5*CU5/(6*CS5^2)-CT5^3/(27*CS5^3)-CV5/(2*CS5))^(1/3)-CT5/(3*CS5) -> 303.43245 | CX5: =((0.85*fc*CW5*BK5)+(CG5*(fy-0.85*fc))-(CG5*600*((0.85*CQ5)-CW5)/CW5))/1000 -> 3839.0801 | CZ5: =0.425*fc*BJ5 -> 3570 | DA5: =2*CZ5*(CI5-CH5) -> -1733631.3 | DB5: =CG5*(fy-0.85*fc)*(CI5-CH5+60)-CG5*fy*CI5 -> -59770953 | DC5: =(-DA5+(DA5^2-4*CZ5*DB5)^0.5)/(2*CZ5) -> 517.93652 | DD5: =600*(DC5/0.85-60)*0.85/DC5 -> 540.9194 | DE5: =IF(DD5>fy,DB5,CG5*(DD5-0.85*fc)*(CI5-CH5+60)-CG5*fy*CI5) -> -59770953 | DF5: =(-DA5+(DA5^2-4*CZ5*DE5)^0.5)/(2*CZ5) -> 517.93652 | DG5: =IF(DD5>fy,(0.85*fc*DF5*BJ5+CG5*(fy-0.85*fc)-CG5*fy),(0.85*fc*DF5*BJ5+CG5*(DD5-0.85*fc)-CG5*fy))/1000 -> 3688.9037 | DI5: =0.425*fc*BK5 -> 5950 | DJ5: =2*DI5*(CR5-CQ5) -> -1782772.6 | DK5: =CG5*(fy-0.85*fc)*(CR5-CQ5+60)-CG5*fy*CR5 -> -28283045 | DL5: =(-DJ5+(DJ5^2-4*DI5*DK5)^0.5)/(2*DI5) -> 314.72897 | DM5: =600*(DL5/0.85-60)*0.85/DC5 -> 305.51502 | DN5: =IF(DM5>fy,DK5,CG5*(DM5-0.85*fc)*(CR5-CQ5+60)-CG5*fy*CR5) -> -24324390 | DO5: =(-DJ5+(DJ5^2-4*DI5*DN5)^0.5)/(2*DI5) -> 312.69934 | DP5: =IF(DM5>fy,(0.85*fc*DO5*BK5+CG5*(fy-0.85*fc)-CG5*fy),(0.85*fc*DO5*BK5+CG5*(DM5-0.85*fc)-CG5*fy))/1000 -> 3667.8824 | DT5: =B5 -> C2 | DU5: =AZ5 -> 10 | DV5: =BA5 -> φ | DW5: =BB5 -> 14
A6: MIDAH | B6: C3 | C6: 14 | D6: 300 | E6: 500 | F6: 1600 | G6: 925.87 | H6: 0.11 | I6: 0 | J6: 0.18 | K6: 0 | L6: =(0.9*F6)/(0.3*E6) -> 9.6 | M6: =IF(P6>Q6,(34-12*I6/H6),(34-12*H6/I6)) -> 34 | N6: =IF(L6<=M6,"sho.col","long.col") -> sho.col | P6: =ABS(H6) -> 0.11 | Q6: =ABS(I6) -> 0 | R6: =ABS(J6) -> 0.18 | S6: =ABS(K6) -> 0 | W6: H | X6: 0 | Y6: 400 | AI6: 3 , 221 , 153 | AJ6: =B6 -> C3 | AL6: 300 | AM6: 500 | AN6: =AM6-60 -> 440 | AO6: =G6 -> 925.87 | AP6: =P6 -> 0.11 | AQ6: =R6 -> 0.18 | AR6: =AP6+(AQ6*AM6/AL6*((1-AS$2)/AS$2)) -> 0.27153846 | AS6: =AQ6+(AP6*AL6/AM6*((1-AS$2)/AS$2)) -> 0.21553846 | AT6: =MAX(AR6:AS6) -> 0.27153846 | AU6: =AT6/AO6 -> 0.00029327925 | AV6: =IF(AU6<=1,"Compression","Tention") -> Compression | AW6: =IF(MAX(AP6*1000/AO6,AQ6*1000/AO6)>0.1*AM6,IF(IF(AV6="Compression",2*(0.5+AU6*10^3/(AN6-BD$2))*(-AL6*AM$2*AM6/(1.18+3*AU6*10^3*AM6/AN6^2)+AO6*10^3/AU$2)/AO$2,2*AO6*1000*(AU6*1000-0.5*AM6+0.2*AN6)/(AU$2*fy*(AN6-BD$2)))<0.01*AL6*AM6,(0.01*AL6*AM6),IF(AV6="Compression",2*(0.5+AU6*10^3/(AN6-60))*(-AL6*AM$2*AM6/(1.18+3*AU6*10^3*AM6/AN6^2)+AO6*10^3/AU$2)/AO$2,2*AO6*1000*(AU6*1000-0.5*AM6+0.2*AN6)/(AU$2*fy*(AN6-BD$2)))),MAX((AO6*1000/(0.8*AU$2)-0.85*fc*AL6*AM6)/(fy-0.85*fc),0.01*AL6*AM6)) -> 1500 | AX6: =AW6/4 -> 375 | AY6: =AW6/(AL6*AM6) -> 0.01 | AZ6: =EVEN(AW6/(PI()*BB6^2/4)) -> 10 | BA6: φ | BB6: 14 | BC6: 0.09 | BD6: =MIN(fc^0.5*AL6*AN6/(6*1000),fc^0.5*(AL6-60)*AM6/(6*1000)) -> 105.83005 | BE6: =(BC6-BF$2*BD6)/BF$2 -> -105.71005 | BF6: =FLOOR(MIN(AL6/2,MIN((3*AZ$2*BI$2/AM6),(16*AZ$2*BI$2/(fc^0.5*AM6))),(8*BB6),(24*AX$2),300),10) -> 110 | BG6: =MAX(MAX(AL6,AM6),(F6/6),450) -> 500 | BH6: =IF(BC6<0.5*BD6*BF$2,"No Need Shear Reinf.",IF(BC6<=BD6*BF$2,BF6,IF(BE6>4*BD6,"Increase b & d",FLOOR(AZ$2*BI$2*AN6/(BE6*1000),50)))) -> No Need Shear Reinf. | BI6: =IF(BH6="No Need Shear Reinf.","Use Φ"&AX$2&"@"&MIN(BF6,BH6)&"mm",IF(BH6="Increase b & d","Increase b & d","Use Φ"&AX$2&"@"&MIN(BF6,BH6)&"mm")) -> Use Φ10@110mm | BJ6: =AL6 -> 300 | BK6: =AM6 -> 500 | BL6: =0.85*(600*AN6)/(600+fy) -> 220 | BM6: =0.85*(600*(BJ6-60))/(600+fy) -> 120 | BN6: =600*(BL6/0.85-60)*0.85/BL6 -> 460.90909 | BO6: =600*(BM6/0.85-60)*0.85/BM6 -> 345 | BP6: =IF(BN6>fy,(0.85*fc*BL6*BJ6+CG6*(fy-0.85*fc)-CG6*fy),(0.85*fc*BL6*BJ6+CG6*(BN6-0.85*fc)-CG6*fy))/1000 -> 1561.637 | BQ6: =IF(BO6>fy,(0.85*fc*BM6*BK6+CG6*(fy-0.85*fc)-CG6*fy),(0.85*fc*BM6*BK6+CG6*(BO6-0.85*fc)-CG6*fy))/1000 -> 1389.962 | BR6: =IF(BN6>fy,(0.85*fc*BL6*BJ6*(BK6/2-BL6/2)+CG6*(fy-0.85*fc)*(BK6/2-60)+CG6*fy*(BK6/2-60)),(0.85*fc*BL6*BJ6*(AN6-BL6/2-60)+CG6*(BN6-0.85*fc)*(BK6/2-60)+CG6*fy*(BK6/2-60)))/1000000 -> 279.61703 | BS6: =IF(BO6>fy,(0.85*fc*BM6*BK6*((BJ6-60)-BM6/2-60)+CG6*(fy-0.85*AM$2)*(BJ6/2-60)-CG6*fy*(BJ6/2-60)),(0.85*fc*BM6*BK6*((BJ6-60)-BM6/2-60)+CG6*(BO6-0.85*fc)*(BJ6/2-60)-CG6*fy*(BJ6/2-60)))/1000000 -> 167.93658 | BT6: =BR6/BP6 -> 0.17905379 | BU6: =BS6/BQ6 -> 0.12082099 | BV6: =AP6/AO6 -> 0.00011880718 | BW6: =AQ6/AO6 -> 0.00019441174 | BX6: =IF(BT6>BV6,"Compression Controls","Tension Controls") -> Compression Controls | BY6: =IF(BU6>BW6,"Compression Controls","Tension Controls") -> Compression Controls | BZ6: =IF(BX6="Compression Controls",CO6,DG6) -> 3850.1328 | CA6: =IF(BY6="Compression Controls",CX6,DP6) -> 3838.8961 | CB6: =(0.85*fc*BJ6*BK6+CG6*4*(fy-0.85*fc))/1000 -> 4180.148 | CC6: =IF(MAX(AP6*1000/AO6,AQ6*1000/AO6)>0.1*AM6,AU$2/(1/BZ6+1/CA6-1/CB6),AU$2*0.8*CB6) -> 2173.677 | CD6: =IF(CC6>=AO6,"Safe ","Unsafe") -> Safe | CG6: =(AZ6*0.25*22/7*BB6^2)/4 -> 385 | CH6: =BK6-60 -> 440 | CI6: =BV6*1000+BK6/2-60 -> 190.11881 | CJ6: =0.85*fc*BJ6/(2*CI6) -> 18.777732 | CK6: =0.85*fc*BJ6*(1-CH6/CI6) -> -9384.4041 | CL6: =(600*CG6+CG6*(fy-0.85*fc)*(1-(CH6-60)/CI6)) -> 78653.644 | CM6: =-510*CH6*CG6 -> -86394000 | CN6: =(((CK6*CL6/(6*CJ6^2)-(CK6/(3*CJ6))^3-CM6/(2*CJ6))^2+(-(CK6^2/(9*CJ6^2))+CL6/(3*CJ6))^3)^0.5+CK6*CL6/(6*CJ6^2)-CK6^3/(27*CJ6^3)-CM6/(2*CJ6))^(1/3)+(-(((CK6*CL6/(6*CJ6^2)-(CK6/(3*CJ6))^3-CM6/(2*CJ6))^2+(-(CK6^2/(9*CJ6^2))+CL6/(3*CJ6))^3)^0.5)+CK6*CL6/(6*CJ6^2)-CK6^3/(27*CJ6^3)-CM6/(2*CJ6))^(1/3)-CK6/(3*CJ6) -> 509.2768 | CO6: =((0.85*fc*CN6*BJ6)+(CG6*(fy-0.85*fc))-(CG6*600*((0.85*CH6)-CN6)/CN6))/1000 -> 3850.1328 | CQ6: =BJ6-60 -> 240 | CR6: =BW6*1000+BJ6/2-60 -> 90.194412 | CS6: =0.85*fc*BK6/(2*CR6) -> 65.96861 | CT6: =0.85*fc*BK6*(1-CQ6/CR6) -> -19764.933 | CU6: =(600*CG6+CG6*(fy-0.85*fc)*(1-(CQ6-60)/CR6)) -> 79120.579 | CV6: =-510*CQ6*CG6 -> -47124000 | CW6: =(((CT6*CU6/(6*CS6^2)-(CT6/(3*CS6))^3-CV6/(2*CS6))^2+(-(CT6^2/(9*CS6^2))+CU6/(3*CS6))^3)^0.5+CT6*CU6/(6*CS6^2)-CT6^3/(27*CS6^3)-CV6/(2*CS6))^(1/3)+(-(((CT6*CU6/(6*CS6^2)-(CT6/(3*CS6))^3-CV6/(2*CS6))^2+(-(CT6^2/(9*CS6^2))+CU6/(3*CS6))^3)^0.5)+CT6*CU6/(6*CS6^2)-CT6^3/(27*CS6^3)-CV6/(2*CS6))^(1/3)-CT6/(3*CS6) -> 303.41763 | CX6: =((0.85*fc*CW6*BK6)+(CG6*(fy-0.85*fc))-(CG6*600*((0.85*CQ6)-CW6)/CW6))/1000 -> 3838.8961 | CZ6: =0.425*fc*BJ6 -> 3570 | DA6: =2*CZ6*(CI6-CH6) -> -1784151.7 | DB6: =CG6*(fy-0.85*fc)*(CI6-CH6+60)-CG6*fy*CI6 -> -59706119 | DC6: =(-DA6+(DA6^2-4*CZ6*DB6)^0.5)/(2*CZ6) -> 531.24397 | DD6: =600*(DC6/0.85-60)*0.85/DC6 -> 542.39935 | DE6: =IF(DD6>fy,DB6,CG6*(DD6-0.85*fc)*(CI6-CH6+60)-CG6*fy*CI6) -> -59706119 | DF6: =(-DA6+(DA6^2-4*CZ6*DE6)^0.5)/(2*CZ6) -> 531.24397 | DG6: =IF(DD6>fy,(0.85*fc*DF6*BJ6+CG6*(fy-0.85*fc)-CG6*fy),(0.85*fc*DF6*BJ6+CG6*(DD6-0.85*fc)-CG6*fy))/1000 -> 3783.919 | DI6: =0.425*fc*BK6 -> 5950 | DJ6: =2*DI6*(CR6-CQ6) -> -1782686.5 | DK6: =CG6*(fy-0.85*fc)*(CR6-CQ6+60)-CG6*fy*CR6 -> -28283111 | DL6: =(-DJ6+(DJ6^2-4*DI6*DK6)^0.5)/(2*DI6) -> 314.71519 | DM6: =600*(DL6/0.85-60)*0.85/DC6 -> 297.84642 | DN6: =IF(DM6>fy,DK6,CG6*(DM6-0.85*fc)*(CR6-CQ6+60)-CG6*fy*CR6) -> -24059633 | DO6: =(-DJ6+(DJ6^2-4*DI6*DN6)^0.5)/(2*DI6) -> 312.54879 | DP6: =IF(DM6>fy,(0.85*fc*DO6*BK6+CG6*(fy-0.85*fc)-CG6*fy),(0.85*fc*DO6*BK6+CG6*(DM6-0.85*fc)-CG6*fy))/1000 -> 3663.1385 | DT6: =B6 -> C3 | DU6: =AZ6 -> 10 | DV6: =BA6 -> φ | DW6: =BB6 -> 14
A7: MIDAH | B7: C7 | C7: 59 | D7: 300 | E7: 500 | F7: 1600 | G7: 696.09 | H7: 30.14 | I7: 0 | J7: 9.64 | K7: 0 | L7: =(0.9*F7)/(0.3*E7) -> 9.6 | M7: =IF(P7>Q7,(34-12*I7/H7),(34-12*H7/I7)) -> 34 | N7: =IF(L7<=M7,"sho.col","long.col") -> sho.col | P7: =ABS(H7) -> 30.14 | Q7: =ABS(I7) -> 0 | R7: =ABS(J7) -> 9.64 | S7: =ABS(K7) -> 0 | W7: L | X7: 0 | Y7: 1100 | Z7: =D5 -> 300 | AA7: =E5 -> 500 | AB7: =F5 -> 1600 | AC7: =(Z7*AA7^3/12)/AB7 -> 1953125 | AI7: 7 , 225 , 157 | AJ7: =B7 -> C7 | AL7: 300 | AM7: 500 | AN7: =AM7-60 -> 440 | AO7: =G7 -> 696.09 | AP7: =P7 -> 30.14 | AQ7: =R7 -> 9.64 | AR7: =AP7+(AQ7*AM7/AL7*((1-AS$2)/AS$2)) -> 38.791282 | AS7: =AQ7+(AP7*AL7/AM7*((1-AS$2)/AS$2)) -> 19.377538 | AT7: =MAX(AR7:AS7) -> 38.791282 | AU7: =AT7/AO7 -> 0.055727395 | AV7: =IF(AU7<=1,"Compression","Tention") -> Compression | AW7: =IF(MAX(AP7*1000/AO7,AQ7*1000/AO7)>0.1*AM7,IF(IF(AV7="Compression",2*(0.5+AU7*10^3/(AN7-BD$2))*(-AL7*AM$2*AM7/(1.18+3*AU7*10^3*AM7/AN7^2)+AO7*10^3/AU$2)/AO$2,2*AO7*1000*(AU7*1000-0.5*AM7+0.2*AN7)/(AU$2*fy*(AN7-BD$2)))<0.01*AL7*AM7,(0.01*AL7*AM7),IF(AV7="Compression",2*(0.5+AU7*10^3/(AN7-60))*(-AL7*AM$2*AM7/(1.18+3*AU7*10^3*AM7/AN7^2)+AO7*10^3/AU$2)/AO$2,2*AO7*1000*(AU7*1000-0.5*AM7+0.2*AN7)/(AU$2*fy*(AN7-BD$2)))),MAX((AO7*1000/(0.8*AU$2)-0.85*fc*AL7*AM7)/(fy-0.85*fc),0.01*AL7*AM7)) -> 1500 | AX7: =AW7/4 -> 375 | AY7: =AW7/(AL7*AM7) -> 0.01 | AZ7: =EVEN(AW7/(PI()*BB7^2/4)) -> 10 | BA7: φ | BB7: 14 | BC7: 15.07 | BD7: =MIN(fc^0.5*AL7*AN7/(6*1000),fc^0.5*(AL7-60)*AM7/(6*1000)) -> 105.83005 | BE7: =(BC7-BF$2*BD7)/BF$2 -> -85.736719 | BF7: =FLOOR(MIN(AL7/2,MIN((3*AZ$2*BI$2/AM7),(16*AZ$2*BI$2/(fc^0.5*AM7))),(8*BB7),(24*AX$2),300),10) -> 110 | BG7: =MAX(MAX(AL7,AM7),(F7/6),450) -> 500 | BH7: =IF(BC7<0.5*BD7*BF$2,"No Need Shear Reinf.",IF(BC7<=BD7*BF$2,BF7,IF(BE7>4*BD7,"Increase b & d",FLOOR(AZ$2*BI$2*AN7/(BE7*1000),50)))) -> No Need Shear Reinf. | BI7: =IF(BH7="No Need Shear Reinf.","Use Φ"&AX$2&"@"&MIN(BF7,BH7)&"mm",IF(BH7="Increase b & d","Increase b & d","Use Φ"&AX$2&"@"&MIN(BF7,BH7)&"mm")) -> Use Φ10@110mm | BJ7: =AL7 -> 300 | BK7: =AM7 -> 500 | BL7: =0.85*(600*AN7)/(600+fy) -> 220 | BM7: =0.85*(600*(BJ7-60))/(600+fy) -> 120 | BN7: =600*(BL7/0.85-60)*0.85/BL7 -> 460.90909 | BO7: =600*(BM7/0.85-60)*0.85/BM7 -> 345 | BP7: =IF(BN7>fy,(0.85*fc*BL7*BJ7+CG7*(fy-0.85*fc)-CG7*fy),(0.85*fc*BL7*BJ7+CG7*(BN7-0.85*fc)-CG7*fy))/1000 -> 1561.637 | BQ7: =IF(BO7>fy,(0.85*fc*BM7*BK7+CG7*(fy-0.85*fc)-CG7*fy),(0.85*fc*BM7*BK7+CG7*(BO7-0.85*fc)-CG7*fy))/1000 -> 1389.962 | BR7: =IF(BN7>fy,(0.85*fc*BL7*BJ7*(BK7/2-BL7/2)+CG7*(fy-0.85*fc)*(BK7/2-60)+CG7*fy*(BK7/2-60)),(0.85*fc*BL7*BJ7*(AN7-BL7/2-60)+CG7*(BN7-0.85*fc)*(BK7/2-60)+CG7*fy*(BK7/2-60)))/1000000 -> 279.61703 | BS7: =IF(BO7>fy,(0.85*fc*BM7*BK7*((BJ7-60)-BM7/2-60)+CG7*(fy-0.85*AM$2)*(BJ7/2-60)-CG7*fy*(BJ7/2-60)),(0.85*fc*BM7*BK7*((BJ7-60)-BM7/2-60)+CG7*(BO7-0.85*fc)*(BJ7/2-60)-CG7*fy*(BJ7/2-60)))/1000000 -> 167.93658 | BT7: =BR7/BP7 -> 0.17905379 | BU7: =BS7/BQ7 -> 0.12082099 | BV7: =AP7/AO7 -> 0.043298999 | BW7: =AQ7/AO7 -> 0.013848784 | BX7: =IF(BT7>BV7,"Compression Controls","Tension Controls") -> Compression Controls | BY7: =IF(BU7>BW7,"Compression Controls","Tension Controls") -> Compression Controls | BZ7: =IF(BX7="Compression Controls",CO7,DG7) -> 3207.0467 | CA7: =IF(BY7="Compression Controls",CX7,DP7) -> 3492.017 | CB7: =(0.85*fc*BJ7*BK7+CG7*4*(fy-0.85*fc))/1000 -> 4180.148 | CC7: =IF(MAX(AP7*1000/AO7,AQ7*1000/AO7)>0.1*AM7,AU$2/(1/BZ7+1/CA7-1/CB7),AU$2*0.8*CB7) -> 2173.677 | CD7: =IF(CC7>=AO7,"Safe ","Unsafe") -> Safe | CG7: =(AZ7*0.25*22/7*BB7^2)/4 -> 385 | CH7: =BK7-60 -> 440 | CI7: =BV7*1000+BK7/2-60 -> 233.299 | CJ7: =0.85*fc*BJ7/(2*CI7) -> 15.302252 | CK7: =0.85*fc*BJ7*(1-CH7/CI7) -> -6325.9815 | CL7: =(600*CG7+CG7*(fy-0.85*fc)*(1-(CH7-60)/CI7)) -> 135083.04 | CM7: =-510*CH7*CG7 -> -86394000 | CN7: =(((CK7*CL7/(6*CJ7^2)-(CK7/(3*CJ7))^3-CM7/(2*CJ7))^2+(-(CK7^2/(9*CJ7^2))+CL7/(3*CJ7))^3)^0.5+CK7*CL7/(6*CJ7^2)-CK7^3/(27*CJ7^3)-CM7/(2*CJ7))^(1/3)+(-(((CK7*CL7/(6*CJ7^2)-(CK7/(3*CJ7))^3-CM7/(2*CJ7))^2+(-(CK7^2/(9*CJ7^2))+CL7/(3*CJ7))^3)^0.5)+CK7*CL7/(6*CJ7^2)-CK7^3/(27*CJ7^3)-CM7/(2*CJ7))^(1/3)-CK7/(3*CJ7) -> 423.98807 | CO7: =((0.85*fc*CN7*BJ7)+(CG7*(fy-0.85*fc))-(CG7*600*((0.85*CH7)-CN7)/CN7))/1000 -> 3207.0467 | CQ7: =BJ7-60 -> 240 | CR7: =BW7*1000+BJ7/2-60 -> 103.84878 | CS7: =0.85*fc*BK7/(2*CR7) -> 57.294845 | CT7: =0.85*fc*BK7*(1-CQ7/CR7) -> -15601.526 | CU7: =(600*CG7+CG7*(fy-0.85*fc)*(1-(CQ7-60)/CR7)) -> 119146.23 | CV7: =-510*CQ7*CG7 -> -47124000 | CW7: =(((CT7*CU7/(6*CS7^2)-(CT7/(3*CS7))^3-CV7/(2*CS7))^2+(-(CT7^2/(9*CS7^2))+CU7/(3*CS7))^3)^0.5+CT7*CU7/(6*CS7^2)-CT7^3/(27*CS7^3)-CV7/(2*CS7))^(1/3)+(-(((CT7*CU7/(6*CS7^2)-(CT7/(3*CS7))^3-CV7/(2*CS7))^2+(-(CT7^2/(9*CS7^2))+CU7/(3*CS7))^3)^0.5)+CT7*CU7/(6*CS7^2)-CT7^3/(27*CS7^3)-CV7/(2*CS7))^(1/3)-CT7/(3*CS7) -> 275.58618 | CX7: =((0.85*fc*CW7*BK7)+(CG7*(fy-0.85*fc))-(CG7*600*((0.85*CQ7)-CW7)/CW7))/1000 -> 3492.017 | CZ7: =0.425*fc*BJ7 -> 3570 | DA7: =2*CZ7*(CI7-CH7) -> -1475845.1 | DB7: =CG7*(fy-0.85*fc)*(CI7-CH7+60)-CG7*fy*CI7 -> -60101779 | DC7: =(-DA7+(DA7^2-4*CZ7*DB7)^0.5)/(2*CZ7) -> 450.75127 | DD7: =600*(DC7/0.85-60)*0.85/DC7 -> 532.11334 | DE7: =IF(DD7>fy,DB7,CG7*(DD7-0.85*fc)*(CI7-CH7+60)-CG7*fy*CI7) -> -60101779 | DF7: =(-DA7+(DA7^2-4*CZ7*DE7)^0.5)/(2*CZ7) -> 450.75127 | DG7: =IF(DD7>fy,(0.85*fc*DF7*BJ7+CG7*(fy-0.85*fc)-CG7*fy),(0.85*fc*DF7*BJ7+CG7*(DD7-0.85*fc)-CG7*fy))/1000 -> 3209.2011 | DI7: =0.425*fc*BK7 -> 5950 | DJ7: =2*DI7*(CR7-CQ7) -> -1620199.5 | DK7: =CG7*(fy-0.85*fc)*(CR7-CQ7+60)-CG7*fy*CR7 -> -28408226 | DL7: =(-DJ7+(DJ7^2-4*DI7*DK7)^0.5)/(2*DI7) -> 288.83273 | DM7: =600*(DL7/0.85-60)*0.85/DC7 -> 316.58178 | DN7: =IF(DM7>fy,DK7,CG7*(DM7-0.85*fc)*(CR7-CQ7+60)-CG7*fy*CR7) -> -25376188 | DO7: =(-DJ7+(DJ7^2-4*DI7*DN7)^0.5)/(2*DI7) -> 287.15472 | DP7: =IF(DM7>fy,(0.85*fc*DO7*BK7+CG7*(fy-0.85*fc)-CG7*fy),(0.85*fc*DO7*BK7+CG7*(DM7-0.85*fc)-CG7*fy))/1000 -> 3368.1622 | DT7: =B7 -> C7 | DU7: =AZ7 -> 10 | DV7: =BA7 -> φ | DW7: =BB7 -> 14
A8: MIDAH | B8: C8 | C8: 23 | D8: 200 | E8: 500 | F8: 1600 | G8: 742.05 | H8: 5.71 | I8: 0 | J8: 10.66 | K8: 0 | L8: =(0.9*F8)/(0.3*E8) -> 9.6 | M8: =IF(P8>Q8,(34-12*I8/H8),(34-12*H8/I8)) -> 34 | N8: =IF(L8<=M8,"sho.col","long.col") -> sho.col | P8: =ABS(H8) -> 5.71 | Q8: =ABS(I8) -> 0 | R8: =ABS(J8) -> 10.66 | S8: =ABS(K8) -> 0 | W8: I/L | X8: 0 | Y8: =(Y5*Y6^3/12)/Y7 -> 969696.97 | AI8: 8 , 226 , 158 | AJ8: =B8 -> C8 | AL8: 200 | AM8: 500 | AN8: =AM8-60 -> 440 | AO8: =G8 -> 742.05 | AP8: =P8 -> 5.71 | AQ8: =R8 -> 10.66 | AR8: =AP8+(AQ8*AM8/AL8*((1-AS$2)/AS$2)) -> 20.06 | AS8: =AQ8+(AP8*AL8/AM8*((1-AS$2)/AS$2)) -> 11.889846 | AT8: =MAX(AR8:AS8) -> 20.06 | AU8: =AT8/AO8 -> 0.027033219 | AV8: =IF(AU8<=1,"Compression","Tention") -> Compression | AW8: =IF(MAX(AP8*1000/AO8,AQ8*1000/AO8)>0.1*AM8,IF(IF(AV8="Compression",2*(0.5+AU8*10^3/(AN8-BD$2))*(-AL8*AM$2*AM8/(1.18+3*AU8*10^3*AM8/AN8^2)+AO8*10^3/AU$2)/AO$2,2*AO8*1000*(AU8*1000-0.5*AM8+0.2*AN8)/(AU$2*fy*(AN8-BD$2)))<0.01*AL8*AM8,(0.01*AL8*AM8),IF(AV8="Compression",2*(0.5+AU8*10^3/(AN8-60))*(-AL8*AM$2*AM8/(1.18+3*AU8*10^3*AM8/AN8^2)+AO8*10^3/AU$2)/AO$2,2*AO8*1000*(AU8*1000-0.5*AM8+0.2*AN8)/(AU$2*fy*(AN8-BD$2)))),MAX((AO8*1000/(0.8*AU$2)-0.85*fc*AL8*AM8)/(fy-0.85*fc),0.01*AL8*AM8)) -> 1000 | AX8: =AW8/4 -> 250 | AY8: =AW8/(AL8*AM8) -> 0.01 | AZ8: =EVEN(AW8/(PI()*BB8^2/4)) -> 8 | BA8: φ | BB8: 14 | BC8: 5.33 | BD8: =MIN(fc^0.5*AL8*AN8/(6*1000),fc^0.5*(AL8-60)*AM8/(6*1000)) -> 61.734197 | BE8: =(BC8-BF$2*BD8)/BF$2 -> -54.627531 | BF8: =FLOOR(MIN(AL8/2,MIN((3*AZ$2*BI$2/AM8),(16*AZ$2*BI$2/(fc^0.5*AM8))),(8*BB8),(24*AX$2),300),10) -> 100 | BG8: =MAX(MAX(AL8,AM8),(F8/6),450) -> 500 | BH8: =IF(BC8<0.5*BD8*BF$2,"No Need Shear Reinf.",IF(BC8<=BD8*BF$2,BF8,IF(BE8>4*BD8,"Increase b & d",FLOOR(AZ$2*BI$2*AN8/(BE8*1000),50)))) -> No Need Shear Reinf. | BI8: =IF(BH8="No Need Shear Reinf.","Use Φ"&AX$2&"@"&MIN(BF8,BH8)&"mm",IF(BH8="Increase b & d","Increase b & d","Use Φ"&AX$2&"@"&MIN(BF8,BH8)&"mm")) -> Use Φ10@100mm | BJ8: =AL8 -> 200 | BK8: =AM8 -> 500 | BL8: =0.85*(600*AN8)/(600+fy) -> 220 | BM8: =0.85*(600*(BJ8-60))/(600+fy) -> 70 | BN8: =600*(BL8/0.85-60)*0.85/BL8 -> 460.90909 | BO8: =600*(BM8/0.85-60)*0.85/BM8 -> 162.85714 | BP8: =IF(BN8>fy,(0.85*fc*BL8*BJ8+CG8*(fy-0.85*fc)-CG8*fy),(0.85*fc*BL8*BJ8+CG8*(BN8-0.85*fc)-CG8*fy))/1000 -> 1039.8696 | BQ8: =IF(BO8>fy,(0.85*fc*BM8*BK8+CG8*(fy-0.85*fc)-CG8*fy),(0.85*fc*BM8*BK8+CG8*(BO8-0.85*fc)-CG8*fy))/1000 -> 746.4696 | BR8: =IF(BN8>fy,(0.85*fc*BL8*BJ8*(BK8/2-BL8/2)+CG8*(fy-0.85*fc)*(BK8/2-60)+CG8*fy*(BK8/2-60)),(0.85*fc*BL8*BJ8*(AN8-BL8/2-60)+CG8*(BN8-0.85*fc)*(BK8/2-60)+CG8*fy*(BK8/2-60)))/1000000 -> 194.37202 | BS8: =IF(BO8>fy,(0.85*fc*BM8*BK8*((BJ8-60)-BM8/2-60)+CG8*(fy-0.85*AM$2)*(BJ8/2-60)-CG8*fy*(BJ8/2-60)),(0.85*fc*BM8*BK8*((BJ8-60)-BM8/2-60)+CG8*(BO8-0.85*fc)*(BJ8/2-60)-CG8*fy*(BJ8/2-60)))/1000000 -> 34.023784 | BT8: =BR8/BP8 -> 0.18691961 | BU8: =BS8/BQ8 -> 0.045579598 | BV8: =AP8/AO8 -> 0.0076948993 | BW8: =AQ8/AO8 -> 0.014365609 | BX8: =IF(BT8>BV8,"Compression Controls","Tension Controls") -> Compression Controls | BY8: =IF(BU8>BW8,"Compression Controls","Tension Controls") -> Compression Controls | BZ8: =IF(BX8="Compression Controls",CO8,DG8) -> 2527.7059 | CA8: =IF(BY8="Compression Controls",CX8,DP8) -> 2217.2665 | CB8: =(0.85*fc*BJ8*BK8+CG8*4*(fy-0.85*fc))/1000 -> 2868.1184 | CC8: =IF(MAX(AP8*1000/AO8,AQ8*1000/AO8)>0.1*AM8,AU$2/(1/BZ8+1/CA8-1/CB8),AU$2*0.8*CB8) -> 1491.4216 | CD8: =IF(CC8>=AO8,"Safe ","Unsafe") -> Safe | CG8: =(AZ8*0.25*22/7*BB8^2)/4 -> 308 | CH8: =BK8-60 -> 440 | CI8: =BV8*1000+BK8/2-60 -> 197.6949 | CJ8: =0.85*fc*BJ8/(2*CI8) -> 12.038753 | CK8: =0.85*fc*BJ8*(1-CH8/CI8) -> -5834.1024 | CL8: =(600*CG8+CG8*(fy-0.85*fc)*(1-(CH8-60)/CI8)) -> 72269.942 | CM8: =-510*CH8*CG8 -> -69115200 | CN8: =(((CK8*CL8/(6*CJ8^2)-(CK8/(3*CJ8))^3-CM8/(2*CJ8))^2+(-(CK8^2/(9*CJ8^2))+CL8/(3*CJ8))^3)^0.5+CK8*CL8/(6*CJ8^2)-CK8^3/(27*CJ8^3)-CM8/(2*CJ8))^(1/3)+(-(((CK8*CL8/(6*CJ8^2)-(CK8/(3*CJ8))^3-CM8/(2*CJ8))^2+(-(CK8^2/(9*CJ8^2))+CL8/(3*CJ8))^3)^0.5)+CK8*CL8/(6*CJ8^2)-CK8^3/(27*CJ8^3)-CM8/(2*CJ8))^(1/3)-CK8/(3*CJ8) -> 495.8535 | CO8: =((0.85*fc*CN8*BJ8)+(CG8*(fy-0.85*fc))-(CG8*600*((0.85*CH8)-CN8)/CN8))/1000 -> 2527.7059 | CQ8: =BJ8-60 -> 140 | CR8: =BW8*1000+BJ8/2-60 -> 54.365609 | CS8: =0.85*fc*BK8/(2*CR8) -> 109.44419 | CT8: =0.85*fc*BK8*(1-CQ8/CR8) -> -18744.373 | CU8: =(600*CG8+CG8*(fy-0.85*fc)*(1-(CQ8-60)/CR8)) -> 127260.78 | CV8: =-510*CQ8*CG8 -> -21991200 | CW8: =(((CT8*CU8/(6*CS8^2)-(CT8/(3*CS8))^3-CV8/(2*CS8))^2+(-(CT8^2/(9*CS8^2))+CU8/(3*CS8))^3)^0.5+CT8*CU8/(6*CS8^2)-CT8^3/(27*CS8^3)-CV8/(2*CS8))^(1/3)+(-(((CT8*CU8/(6*CS8^2)-(CT8/(3*CS8))^3-CV8/(2*CS8))^2+(-(CT8^2/(9*CS8^2))+CU8/(3*CS8))^3)^0.5)+CT8*CU8/(6*CS8^2)-CT8^3/(27*CS8^3)-CV8/(2*CS8))^(1/3)-CT8/(3*CS8) -> 171.32729 | CX8: =((0.85*fc*CW8*BK8)+(CG8*(fy-0.85*fc))-(CG8*600*((0.85*CQ8)-CW8)/CW8))/1000 -> 2217.2665 | CZ8: =0.425*fc*BJ8 -> 2380 | DA8: =2*CZ8*(CI8-CH8) -> -1153372.3 | DB8: =CG8*(fy-0.85*fc)*(CI8-CH8+60)-CG8*fy*CI8 -> -47820431 | DC8: =(-DA8+(DA8^2-4*CZ8*DB8)^0.5)/(2*CZ8) -> 523.02628 | DD8: =600*(DC8/0.85-60)*0.85/DC8 -> 541.49434 | DE8: =IF(DD8>fy,DB8,CG8*(DD8-0.85*fc)*(CI8-CH8+60)-CG8*fy*CI8) -> -47820431 | DF8: =(-DA8+(DA8^2-4*CZ8*DE8)^0.5)/(2*CZ8) -> 523.02628 | DG8: =IF(DD8>fy,(0.85*fc*DF8*BJ8+CG8*(fy-0.85*fc)-CG8*fy),(0.85*fc*DF8*BJ8+CG8*(DD8-0.85*fc)-CG8*fy))/1000 -> 2482.2747 | DI8: =0.425*fc*BK8 -> 5950 | DJ8: =2*DI8*(CR8-CQ8) -> -1019049.3 | DK8: =CG8*(fy-0.85*fc)*(CR8-CQ8+60)-CG8*fy*CR8 -> -10160890 | DL8: =(-DJ8+(DJ8^2-4*DI8*DK8)^0.5)/(2*DI8) -> 180.71836 | DM8: =600*(DL8/0.85-60)*0.85/DC8 -> 148.809 | DN8: =IF(DM8>fy,DK8,CG8*(DM8-0.85*fc)*(CR8-CQ8+60)-CG8*fy*CR8) -> -8019730.3 | DO8: =(-DJ8+(DJ8^2-4*DI8*DN8)^0.5)/(2*DI8) -> 178.80683 | DP8: =IF(DM8>fy,(0.85*fc*DO8*BK8+CG8*(fy-0.85*fc)-CG8*fy),(0.85*fc*DO8*BK8+CG8*(DM8-0.85*fc)-CG8*fy))/1000 -> 2036.944 | DT8: =B8 -> C8 | DU8: =AZ8 -> 8 | DV8: =BA8 -> φ | DW8: =BB8 -> 14
A9: MIDAH | B9: C9 | C9: 26 | D9: 300 | E9: 600 | F9: 1600 | G9: 842.21 | H9: 6.51 | I9: 0 | J9: -7.5 | K9: 0 | L9: =(0.9*F9)/(0.3*E9) -> 8 | M9: =IF(P9>Q9,(34-12*I9/H9),(34-12*H9/I9)) -> 34 | N9: =IF(L9<=M9,"sho.col","long.col") -> sho.col | P9: =ABS(H9) -> 6.51 | Q9: =ABS(I9) -> 0 | R9: =ABS(J9) -> 7.5 | S9: =ABS(K9) -> 0 | V9: Bottom | W9: B | X9: 0 | AC9: 0 | AD9: 1 | AI9: 9 , 227 ,159 | AJ9: =B9 -> C9 | AL9: 300 | AM9: 600 | AN9: =AM9-60 -> 540 | AO9: =G9 -> 842.21 | AP9: =P9 -> 6.51 | AQ9: =R9 -> 7.5 | AR9: =AP9+(AQ9*AM9/AL9*((1-AS$2)/AS$2)) -> 14.586923 | AS9: =AQ9+(AP9*AL9/AM9*((1-AS$2)/AS$2)) -> 9.2526923 | AT9: =MAX(AR9:AS9) -> 14.586923 | AU9: =AT9/AO9 -> 0.017319817 | AV9: =IF(AU9<=1,"Compression","Tention") -> Compression | AW9: =IF(MAX(AP9*1000/AO9,AQ9*1000/AO9)>0.1*AM9,IF(IF(AV9="Compression",2*(0.5+AU9*10^3/(AN9-BD$2))*(-AL9*AM$2*AM9/(1.18+3*AU9*10^3*AM9/AN9^2)+AO9*10^3/AU$2)/AO$2,2*AO9*1000*(AU9*1000-0.5*AM9+0.2*AN9)/(AU$2*fy*(AN9-BD$2)))<0.01*AL9*AM9,(0.01*AL9*AM9),IF(AV9="Compression",2*(0.5+AU9*10^3/(AN9-60))*(-AL9*AM$2*AM9/(1.18+3*AU9*10^3*AM9/AN9^2)+AO9*10^3/AU$2)/AO$2,2*AO9*1000*(AU9*1000-0.5*AM9+0.2*AN9)/(AU$2*fy*(AN9-BD$2)))),MAX((AO9*1000/(0.8*AU$2)-0.85*fc*AL9*AM9)/(fy-0.85*fc),0.01*AL9*AM9)) -> 1800 | AX9: =AW9/4 -> 450 | AY9: =AW9/(AL9*AM9) -> 0.01 | AZ9: =EVEN(AW9/(PI()*BB9^2/4)) -> 12 | BA9: φ | BB9: 14 | BC9: 3.75 | BD9: =MIN(fc^0.5*AL9*AN9/(6*1000),fc^0.5*(AL9-60)*AM9/(6*1000)) -> 126.99606 | BE9: =(BC9-BF$2*BD9)/BF$2 -> -121.99606 | BF9: =FLOOR(MIN(AL9/2,MIN((3*AZ$2*BI$2/AM9),(16*AZ$2*BI$2/(fc^0.5*AM9))),(8*BB9),(24*AX$2),300),10) -> 110 | BG9: =MAX(MAX(AL9,AM9),(F9/6),450) -> 600 | BH9: =IF(BC9<0.5*BD9*BF$2,"No Need Shear Reinf.",IF(BC9<=BD9*BF$2,BF9,IF(BE9>4*BD9,"Increase b & d",FLOOR(AZ$2*BI$2*AN9/(BE9*1000),50)))) -> No Need Shear Reinf. | BI9: =IF(BH9="No Need Shear Reinf.","Use Φ"&AX$2&"@"&MIN(BF9,BH9)&"mm",IF(BH9="Increase b & d","Increase b & d","Use Φ"&AX$2&"@"&MIN(BF9,BH9)&"mm")) -> Use Φ10@110mm | BJ9: =AL9 -> 300 | BK9: =AM9 -> 600 | BL9: =0.85*(600*AN9)/(600+fy) -> 270 | BM9: =0.85*(600*(BJ9-60))/(600+fy) -> 120 | BN9: =600*(BL9/0.85-60)*0.85/BL9 -> 486.66667 | BO9: =600*(BM9/0.85-60)*0.85/BM9 -> 345 | BP9: =IF(BN9>fy,(0.85*fc*BL9*BJ9+CG9*(fy-0.85*fc)-CG9*fy),(0.85*fc*BL9*BJ9+CG9*(BN9-0.85*fc)-CG9*fy))/1000 -> 1916.8044 | BQ9: =IF(BO9>fy,(0.85*fc*BM9*BK9+CG9*(fy-0.85*fc)-CG9*fy),(0.85*fc*BM9*BK9+CG9*(BO9-0.85*fc)-CG9*fy))/1000 -> 1667.9544 | BR9: =IF(BN9>fy,(0.85*fc*BL9*BJ9*(BK9/2-BL9/2)+CG9*(fy-0.85*fc)*(BK9/2-60)+CG9*fy*(BK9/2-60)),(0.85*fc*BL9*BJ9*(AN9-BL9/2-60)+CG9*(BN9-0.85*fc)*(BK9/2-60)+CG9*fy*(BK9/2-60)))/1000000 -> 408.58726 | BS9: =IF(BO9>fy,(0.85*fc*BM9*BK9*((BJ9-60)-BM9/2-60)+CG9*(fy-0.85*AM$2)*(BJ9/2-60)-CG9*fy*(BJ9/2-60)),(0.85*fc*BM9*BK9*((BJ9-60)-BM9/2-60)+CG9*(BO9-0.85*fc)*(BJ9/2-60)-CG9*fy*(BJ9/2-60)))/1000000 -> 201.5239 | BT9: =BR9/BP9 -> 0.21316064 | BU9: =BS9/BQ9 -> 0.12082099 | BV9: =AP9/AO9 -> 0.0077296636 | BW9: =AQ9/AO9 -> 0.0089051424 | BX9: =IF(BT9>BV9,"Compression Controls","Tension Controls") -> Compression Controls | BY9: =IF(BU9>BW9,"Compression Controls","Tension Controls") -> Compression Controls | BZ9: =IF(BX9="Compression Controls",CO9,DG9) -> 4509.9912 | CA9: =IF(BY9="Compression Controls",CX9,DP9) -> 4341.009 | CB9: =(0.85*fc*BJ9*BK9+CG9*4*(fy-0.85*fc))/1000 -> 5016.1776 | CC9: =IF(MAX(AP9*1000/AO9,AQ9*1000/AO9)>0.1*AM9,AU$2/(1/BZ9+1/CA9-1/CB9),AU$2*0.8*CB9) -> 2608.4124 | CD9: =IF(CC9>=AO9,"Safe ","Unsafe") -> Safe | CG9: =(AZ9*0.25*22/7*BB9^2)/4 -> 462 | CH9: =BK9-60 -> 540 | CI9: =BV9*1000+BK9/2-60 -> 247.72966 | CJ9: =0.85*fc*BJ9/(2*CI9) -> 14.41087 | CK9: =0.85*fc*BJ9*(1-CH9/CI9) -> -8423.7397 | CL9: =(600*CG9+CG9*(fy-0.85*fc)*(1-(CH9-60)/CI9)) -> 105578.31 | CM9: =-510*CH9*CG9 -> -127234800 | CN9: =(((CK9*CL9/(6*CJ9^2)-(CK9/(3*CJ9))^3-CM9/(2*CJ9))^2+(-(CK9^2/(9*CJ9^2))+CL9/(3*CJ9))^3)^0.5+CK9*CL9/(6*CJ9^2)-CK9^3/(27*CJ9^3)-CM9/(2*CJ9))^(1/3)+(-(((CK9*CL9/(6*CJ9^2)-(CK9/(3*CJ9))^3-CM9/(2*CJ9))^2+(-(CK9^2/(9*CJ9^2))+CL9/(3*CJ9))^3)^0.5)+CK9*CL9/(6*CJ9^2)-CK9^3/(27*CJ9^3)-CM9/(2*CJ9))^(1/3)-CK9/(3*CJ9) -> 597.03874 | CO9: =((0.85*fc*CN9*BJ9)+(CG9*(fy-0.85*fc))-(CG9*600*((0.85*CH9)-CN9)/CN9))/1000 -> 4509.9912 | CQ9: =BJ9-60 -> 240 | CR9: =BW9*1000+BJ9/2-60 -> 98.905142 | CS9: =0.85*fc*BK9/(2*CR9) -> 72.190382 | CT9: =0.85*fc*BK9*(1-CQ9/CR9) -> -20371.383 | CU9: =(600*CG9+CG9*(fy-0.85*fc)*(1-(CQ9-60)/CR9)) -> 127117.21 | CV9: =-510*CQ9*CG9 -> -56548800 | CW9: =(((CT9*CU9/(6*CS9^2)-(CT9/(3*CS9))^3-CV9/(2*CS9))^2+(-(CT9^2/(9*CS9^2))+CU9/(3*CS9))^3)^0.5+CT9*CU9/(6*CS9^2)-CT9^3/(27*CS9^3)-CV9/(2*CS9))^(1/3)+(-(((CT9*CU9/(6*CS9^2)-(CT9/(3*CS9))^3-CV9/(2*CS9))^2+(-(CT9^2/(9*CS9^2))+CU9/(3*CS9))^3)^0.5)+CT9*CU9/(6*CS9^2)-CT9^3/(27*CS9^3)-CV9/(2*CS9))^(1/3)-CT9/(3*CS9) -> 285.62649 | CX9: =((0.85*fc*CW9*BK9)+(CG9*(fy-0.85*fc))-(CG9*600*((0.85*CQ9)-CW9)/CW9))/1000 -> 4341.009 | CZ9: =0.425*fc*BJ9 -> 3570 | DA9: =2*CZ9*(CI9-CH9) -> -2086810.2 | DB9: =CG9*(fy-0.85*fc)*(CI9-CH9+60)-CG9*fy*CI9 -> -90585248 | DC9: =(-DA9+(DA9^2-4*CZ9*DB9)^0.5)/(2*CZ9) -> 625.13062 | DD9: =600*(DC9/0.85-60)*0.85/DC9 -> 551.05023 | DE9: =IF(DD9>fy,DB9,CG9*(DD9-0.85*fc)*(CI9-CH9+60)-CG9*fy*CI9) -> -90585248 | DF9: =(-DA9+(DA9^2-4*CZ9*DE9)^0.5)/(2*CZ9) -> 625.13062 | DG9: =IF(DD9>fy,(0.85*fc*DF9*BJ9+CG9*(fy-0.85*fc)-CG9*fy),(0.85*fc*DF9*BJ9+CG9*(DD9-0.85*fc)-CG9*fy))/1000 -> 4452.437 | DI9: =0.425*fc*BK9 -> 7140 | DJ9: =2*DI9*(CR9-CQ9) -> -2014834.6 | DK9: =CG9*(fy-0.85*fc)*(CR9-CQ9+60)-CG9*fy*CR9 -> -34035513 | DL9: =(-DJ9+(DJ9^2-4*DI9*DK9)^0.5)/(2*DI9) -> 298.17648 | DM9: =600*(DL9/0.85-60)*0.85/DC9 -> 237.23984 | DN9: =IF(DM9>fy,DK9,CG9*(DM9-0.85*fc)*(CR9-CQ9+60)-CG9*fy*CR9) -> -27188253 | DO9: =(-DJ9+(DJ9^2-4*DI9*DN9)^0.5)/(2*DI9) -> 295.09368 | DP9: =IF(DM9>fy,(0.85*fc*DO9*BK9+CG9*(fy-0.85*fc)-CG9*fy),(0.85*fc*DO9*BK9+CG9*(DM9-0.85*fc)-CG9*fy))/1000 -> 4118.507 | DT9: =B9 -> C9 | DU9: =AZ9 -> 12 | DV9: =BA9 -> φ | DW9: =BB9 -> 14
A10: MIDAH | B10: C11 | C10: 35 | D10: 200 | E10: 500 | F10: 1600 | G10: 480.98 | H10: 32.19 | I10: 0 | J10: 0.5 | K10: 0 | L10: =(0.9*F10)/(0.3*E10) -> 9.6 | M10: =IF(P10>Q10,(34-12*I10/H10),(34-12*H10/I10)) -> 34 | N10: =IF(L10<=M10,"sho.col","long.col") -> sho.col | P10: =ABS(H10) -> 32.19 | Q10: =ABS(I10) -> 0 | R10: =ABS(J10) -> 0.5 | S10: =ABS(K10) -> 0 | W10: H | X10: 0 | AI10: 11 , 229 ,161 | AJ10: =B10 -> C11 | AL10: 200 | AM10: 500 | AN10: =AM10-60 -> 440 | AO10: =G10 -> 480.98 | AP10: =P10 -> 32.19 | AQ10: =R10 -> 0.5 | AR10: =AP10+(AQ10*AM10/AL10*((1-AS$2)/AS$2)) -> 32.863077 | AS10: =AQ10+(AP10*AL10/AM10*((1-AS$2)/AS$2)) -> 7.4332308 | AT10: =MAX(AR10:AS10) -> 32.863077 | AU10: =AT10/AO10 -> 0.068325246 | AV10: =IF(AU10<=1,"Compression","Tention") -> Compression | AW10: =IF(MAX(AP10*1000/AO10,AQ10*1000/AO10)>0.1*AM10,IF(IF(AV10="Compression",2*(0.5+AU10*10^3/(AN10-BD$2))*(-AL10*AM$2*AM10/(1.18+3*AU10*10^3*AM10/AN10^2)+AO10*10^3/AU$2)/AO$2,2*AO10*1000*(AU10*1000-0.5*AM10+0.2*AN10)/(AU$2*fy*(AN10-BD$2)))<0.01*AL10*AM10,(0.01*AL10*AM10),IF(AV10="Compression",2*(0.5+AU10*10^3/(AN10-60))*(-AL10*AM$2*AM10/(1.18+3*AU10*10^3*AM10/AN10^2)+AO10*10^3/AU$2)/AO$2,2*AO10*1000*(AU10*1000-0.5*AM10+0.2*AN10)/(AU$2*fy*(AN10-BD$2)))),MAX((AO10*1000/(0.8*AU$2)-0.85*fc*AL10*AM10)/(fy-0.85*fc),0.01*AL10*AM10)) -> 1000 | AX10: =AW10/4 -> 250 | AY10: =AW10/(AL10*AM10) -> 0.01 | AZ10: =EVEN(AW10/(PI()*BB10^2/4)) -> 8 | BA10: φ | BB10: 14 | BC10: 16.1 | BD10: =MIN(fc^0.5*AL10*AN10/(6*1000),fc^0.5*(AL10-60)*AM10/(6*1000)) -> 61.734197 | BE10: =(BC10-BF$2*BD10)/BF$2 -> -40.267531 | BF10: =FLOOR(MIN(AL10/2,MIN((3*AZ$2*BI$2/AM10),(16*AZ$2*BI$2/(fc^0.5*AM10))),(8*BB10),(24*AX$2),300),10) -> 100 | BG10: =MAX(MAX(AL10,AM10),(F10/6),450) -> 500 | BH10: =IF(BC10<0.5*BD10*BF$2,"No Need Shear Reinf.",IF(BC10<=BD10*BF$2,BF10,IF(BE10>4*BD10,"Increase b & d",FLOOR(AZ$2*BI$2*AN10/(BE10*1000),50)))) -> No Need Shear Reinf. | BI10: =IF(BH10="No Need Shear Reinf.","Use Φ"&AX$2&"@"&MIN(BF10,BH10)&"mm",IF(BH10="Increase b & d","Increase b & d","Use Φ"&AX$2&"@"&MIN(BF10,BH10)&"mm")) -> Use Φ10@100mm | BJ10: =AL10 -> 200 | BK10: =AM10 -> 500 | BL10: =0.85*(600*AN10)/(600+fy) -> 220 | BM10: =0.85*(600*(BJ10-60))/(600+fy) -> 70 | BN10: =600*(BL10/0.85-60)*0.85/BL10 -> 460.90909 | BO10: =600*(BM10/0.85-60)*0.85/BM10 -> 162.85714 | BP10: =IF(BN10>fy,(0.85*fc*BL10*BJ10+CG10*(fy-0.85*fc)-CG10*fy),(0.85*fc*BL10*BJ10+CG10*(BN10-0.85*fc)-CG10*fy))/1000 -> 1039.8696 | BQ10: =IF(BO10>fy,(0.85*fc*BM10*BK10+CG10*(fy-0.85*fc)-CG10*fy),(0.85*fc*BM10*BK10+CG10*(BO10-0.85*fc)-CG10*fy))/1000 -> 746.4696 | BR10: =IF(BN10>fy,(0.85*fc*BL10*BJ10*(BK10/2-BL10/2)+CG10*(fy-0.85*fc)*(BK10/2-60)+CG10*fy*(BK10/2-60)),(0.85*fc*BL10*BJ10*(AN10-BL10/2-60)+CG10*(BN10-0.85*fc)*(BK10/2-60)+CG10*fy*(BK10/2-60)))/1000000 -> 194.37202 | BS10: =IF(BO10>fy,(0.85*fc*BM10*BK10*((BJ10-60)-BM10/2-60)+CG10*(fy-0.85*AM$2)*(BJ10/2-60)-CG10*fy*(BJ10/2-60)),(0.85*fc*BM10*BK10*((BJ10-60)-BM10/2-60)+CG10*(BO10-0.85*fc)*(BJ10/2-60)-CG10*fy*(BJ10/2-60)))/1000000 -> 34.023784 | BT10: =BR10/BP10 -> 0.18691961 | BU10: =BS10/BQ10 -> 0.045579598 | BV10: =AP10/AO10 -> 0.06692586 | BW10: =AQ10/AO10 -> 0.0010395443 | BX10: =IF(BT10>BV10,"Compression Controls","Tension Controls") -> Compression Controls | BY10: =IF(BU10>BW10,"Compression Controls","Tension Controls") -> Compression Controls | BZ10: =IF(BX10="Compression Controls",CO10,DG10) -> 1942.3208 | CA10: =IF(BY10="Compression Controls",CX10,DP10) -> 2568.8045 | CB10: =(0.85*fc*BJ10*BK10+CG10*4*(fy-0.85*fc))/1000 -> 2868.1184 | CC10: =IF(MAX(AP10*1000/AO10,AQ10*1000/AO10)>0.1*AM10,AU$2/(1/BZ10+1/CA10-1/CB10),AU$2*0.8*CB10) -> 1170.1728 | CD10: =IF(CC10>=AO10,"Safe ","Unsafe") -> Safe | CG10: =(AZ10*0.25*22/7*BB10^2)/4 -> 308 | CH10: =BK10-60 -> 440 | CI10: =BV10*1000+BK10/2-60 -> 256.92586 | CJ10: =0.85*fc*BJ10/(2*CI10) -> 9.2633727 | CK10: =0.85*fc*BJ10*(1-CH10/CI10) -> -3391.768 | CL10: =(600*CG10+CG10*(fy-0.85*fc)*(1-(CH10-60)/CI10)) -> 126344.66 | CM10: =-510*CH10*CG10 -> -69115200 | CN10: =(((CK10*CL10/(6*CJ10^2)-(CK10/(3*CJ10))^3-CM10/(2*CJ10))^2+(-(CK10^2/(9*CJ10^2))+CL10/(3*CJ10))^3)^0.5+CK10*CL10/(6*CJ10^2)-CK10^3/(27*CJ10^3)-CM10/(2*CJ10))^(1/3)+(-(((CK10*CL10/(6*CJ10^2)-(CK10/(3*CJ10))^3-CM10/(2*CJ10))^2+(-(CK10^2/(9*CJ10^2))+CL10/(3*CJ10))^3)^0.5)+CK10*CL10/(6*CJ10^2)-CK10^3/(27*CJ10^3)-CM10/(2*CJ10))^(1/3)-CK10/(3*CJ10) -> 381.6372 | CO10: =((0.85*fc*CN10*BJ10)+(CG10*(fy-0.85*fc))-(CG10*600*((0.85*CH10)-CN10)/CN10))/1000 -> 1942.3208 | CQ10: =BJ10-60 -> 140 | CR10: =BW10*1000+BJ10/2-60 -> 41.039544 | CS10: =0.85*fc*BK10/(2*CR10) -> 144.98212 | CT10: =0.85*fc*BK10*(1-CQ10/CR10) -> -28694.993 | CU10: =(600*CG10+CG10*(fy-0.85*fc)*(1-(CQ10-60)/CR10)) -> 68952.495 | CV10: =-510*CQ10*CG10 -> -21991200 | CW10: =(((CT10*CU10/(6*CS10^2)-(CT10/(3*CS10))^3-CV10/(2*CS10))^2+(-(CT10^2/(9*CS10^2))+CU10/(3*CS10))^3)^0.5+CT10*CU10/(6*CS10^2)-CT10^3/(27*CS10^3)-CV10/(2*CS10))^(1/3)+(-(((CT10*CU10/(6*CS10^2)-(CT10/(3*CS10))^3-CV10/(2*CS10))^2+(-(CT10^2/(9*CS10^2))+CU10/(3*CS10))^3)^0.5)+CT10*CU10/(6*CS10^2)-CT10^3/(27*CS10^3)-CV10/(2*CS10))^(1/3)-CT10/(3*CS10) -> 199.35196 | CX10: =((0.85*fc*CW10*BK10)+(CG10*(fy-0.85*fc))-(CG10*600*((0.85*CQ10)-CW10)/CW10))/1000 -> 2568.8045 | CZ10: =0.425*fc*BJ10 -> 2380 | DA10: =2*CZ10*(CI10-CH10) -> -871432.91 | DB10: =CG10*(fy-0.85*fc)*(CI10-CH10+60)-CG10*fy*CI10 -> -48254617 | DC10: =(-DA10+(DA10^2-4*CZ10*DB10)^0.5)/(2*CZ10) -> 415.00342 | DD10: =600*(DC10/0.85-60)*0.85/DC10 -> 526.26567 | DE10: =IF(DD10>fy,DB10,CG10*(DD10-0.85*fc)*(CI10-CH10+60)-CG10*fy*CI10) -> -48254617 | DF10: =(-DA10+(DA10^2-4*CZ10*DE10)^0.5)/(2*CZ10) -> 415.00342 | DG10: =IF(DD10>fy,(0.85*fc*DF10*BJ10+CG10*(fy-0.85*fc)-CG10*fy),(0.85*fc*DF10*BJ10+CG10*(DD10-0.85*fc)-CG10*fy))/1000 -> 1968.0859 | DI10: =0.425*fc*BK10 -> 5950 | DJ10: =2*DI10*(CR10-CQ10) -> -1177629.4 | DK10: =CG10*(fy-0.85*fc)*(CR10-CQ10+60)-CG10*fy*CR10 -> -10063204 | DL10: =(-DJ10+(DJ10^2-4*DI10*DK10)^0.5)/(2*DI10) -> 206.12606 | DM10: =600*(DL10/0.85-60)*0.85/DC10 -> 224.27679 | DN10: =IF(DM10>fy,DK10,CG10*(DM10-0.85*fc)*(CR10-CQ10+60)-CG10*fy*CR10) -> -7714560.9 | DO10: =(-DJ10+(DJ10^2-4*DI10*DN10)^0.5)/(2*DI10) -> 204.26827 | DP10: =IF(DM10>fy,(0.85*fc*DO10*BK10+CG10*(fy-0.85*fc)-CG10*fy),(0.85*fc*DO10*BK10+CG10*(DM10-0.85*fc)-CG10*fy))/1000 -> 2363.1793 | DT10: =B10 -> C11 | DU10: =AZ10 -> 8 | DV10: =BA10 -> φ | DW10: =BB10 -> 14
A11: MIDAH | B11: C12 | C11: 38 | D11: 200 | E11: 500 | F11: 1600 | G11: 847.58 | H11: 10.48 | I11: 0 | J11: 9.45 | K11: 0 | L11: =(0.9*F11)/(0.3*E11) -> 9.6 | M11: =IF(P11>Q11,(34-12*I11/H11),(34-12*H11/I11)) -> 34 | N11: =IF(L11<=M11,"sho.col","long.col") -> sho.col | P11: =ABS(H11) -> 10.48 | Q11: =ABS(I11) -> 0 | R11: =ABS(J11) -> 9.45 | S11: =ABS(K11) -> 0 | W11: L | X11: 0 | Z11: 0 | AA11: 0 | AB11: 0 | AC11: 0 | AI11: 12 , 230 , 162 | AJ11: =B11 -> C12 | AL11: 200 | AM11: 500 | AN11: =AM11-60 -> 440 | AO11: =G11 -> 847.58 | AP11: =P11 -> 10.48 | AQ11: =R11 -> 9.45 | AR11: =AP11+(AQ11*AM11/AL11*((1-AS$2)/AS$2)) -> 23.201154 | AS11: =AQ11+(AP11*AL11/AM11*((1-AS$2)/AS$2)) -> 11.707231 | AT11: =MAX(AR11:AS11) -> 23.201154 | AU11: =AT11/AO11 -> 0.027373409 | AV11: =IF(AU11<=1,"Compression","Tention") -> Compression | AW11: =IF(MAX(AP11*1000/AO11,AQ11*1000/AO11)>0.1*AM11,IF(IF(AV11="Compression",2*(0.5+AU11*10^3/(AN11-BD$2))*(-AL11*AM$2*AM11/(1.18+3*AU11*10^3*AM11/AN11^2)+AO11*10^3/AU$2)/AO$2,2*AO11*1000*(AU11*1000-0.5*AM11+0.2*AN11)/(AU$2*fy*(AN11-BD$2)))<0.01*AL11*AM11,(0.01*AL11*AM11),IF(AV11="Compression",2*(0.5+AU11*10^3/(AN11-60))*(-AL11*AM$2*AM11/(1.18+3*AU11*10^3*AM11/AN11^2)+AO11*10^3/AU$2)/AO$2,2*AO11*1000*(AU11*1000-0.5*AM11+0.2*AN11)/(AU$2*fy*(AN11-BD$2)))),MAX((AO11*1000/(0.8*AU$2)-0.85*fc*AL11*AM11)/(fy-0.85*fc),0.01*AL11*AM11)) -> 1000 | AX11: =AW11/4 -> 250 | AY11: =AW11/(AL11*AM11) -> 0.01 | AZ11: =EVEN(AW11/(PI()*BB11^2/4)) -> 8 | BA11: φ | BB11: 14 | BC11: 5.24 | BD11: =MIN(fc^0.5*AL11*AN11/(6*1000),fc^0.5*(AL11-60)*AM11/(6*1000)) -> 61.734197 | BE11: =(BC11-BF$2*BD11)/BF$2 -> -54.747531 | BF11: =FLOOR(MIN(AL11/2,MIN((3*AZ$2*BI$2/AM11),(16*AZ$2*BI$2/(fc^0.5*AM11))),(8*BB11),(24*AX$2),300),10) -> 100 | BG11: =MAX(MAX(AL11,AM11),(F11/6),450) -> 500 | BH11: =IF(BC11<0.5*BD11*BF$2,"No Need Shear Reinf.",IF(BC11<=BD11*BF$2,BF11,IF(BE11>4*BD11,"Increase b & d",FLOOR(AZ$2*BI$2*AN11/(BE11*1000),50)))) -> No Need Shear Reinf. | BI11: =IF(BH11="No Need Shear Reinf.","Use Φ"&AX$2&"@"&MIN(BF11,BH11)&"mm",IF(BH11="Increase b & d","Increase b & d","Use Φ"&AX$2&"@"&MIN(BF11,BH11)&"mm")) -> Use Φ10@100mm | BJ11: =AL11 -> 200 | BK11: =AM11 -> 500 | BL11: =0.85*(600*AN11)/(600+fy) -> 220 | BM11: =0.85*(600*(BJ11-60))/(600+fy) -> 70 | BN11: =600*(BL11/0.85-60)*0.85/BL11 -> 460.90909 | BO11: =600*(BM11/0.85-60)*0.85/BM11 -> 162.85714 | BP11: =IF(BN11>fy,(0.85*fc*BL11*BJ11+CG11*(fy-0.85*fc)-CG11*fy),(0.85*fc*BL11*BJ11+CG11*(BN11-0.85*fc)-CG11*fy))/1000 -> 1039.8696 | BQ11: =IF(BO11>fy,(0.85*fc*BM11*BK11+CG11*(fy-0.85*fc)-CG11*fy),(0.85*fc*BM11*BK11+CG11*(BO11-0.85*fc)-CG11*fy))/1000 -> 746.4696 | BR11: =IF(BN11>fy,(0.85*fc*BL11*BJ11*(BK11/2-BL11/2)+CG11*(fy-0.85*fc)*(BK11/2-60)+CG11*fy*(BK11/2-60)),(0.85*fc*BL11*BJ11*(AN11-BL11/2-60)+CG11*(BN11-0.85*fc)*(BK11/2-60)+CG11*fy*(BK11/2-60)))/1000000 -> 194.37202 | BS11: =IF(BO11>fy,(0.85*fc*BM11*BK11*((BJ11-60)-BM11/2-60)+CG11*(fy-0.85*AM$2)*(BJ11/2-60)-CG11*fy*(BJ11/2-60)),(0.85*fc*BM11*BK11*((BJ11-60)-BM11/2-60)+CG11*(BO11-0.85*fc)*(BJ11/2-60)-CG11*fy*(BJ11/2-60)))/1000000 -> 34.023784 | BT11: =BR11/BP11 -> 0.18691961 | BU11: =BS11/BQ11 -> 0.045579598 | BV11: =AP11/AO11 -> 0.012364615 | BW11: =AQ11/AO11 -> 0.01114939 | BX11: =IF(BT11>BV11,"Compression Controls","Tension Controls") -> Compression Controls | BY11: =IF(BU11>BW11,"Compression Controls","Tension Controls") -> Compression Controls | BZ11: =IF(BX11="Compression Controls",CO11,DG11) -> 2480.613 | CA11: =IF(BY11="Compression Controls",CX11,DP11) -> 2302.2998 | CB11: =(0.85*fc*BJ11*BK11+CG11*4*(fy-0.85*fc))/1000 -> 2868.1184 | CC11: =IF(MAX(AP11*1000/AO11,AQ11*1000/AO11)>0.1*AM11,AU$2/(1/BZ11+1/CA11-1/CB11),AU$2*0.8*CB11) -> 1491.4216 | CD11: =IF(CC11>=AO11,"Safe ","Unsafe") -> Safe | CG11: =(AZ11*0.25*22/7*BB11^2)/4 -> 308 | CH11: =BK11-60 -> 440 | CI11: =BV11*1000+BK11/2-60 -> 202.36461 | CJ11: =0.85*fc*BJ11/(2*CI11) -> 11.760949 | CK11: =0.85*fc*BJ11*(1-CH11/CI11) -> -5589.6355 | CL11: =(600*CG11+CG11*(fy-0.85*fc)*(1-(CH11-60)/CI11)) -> 77682.582 | CM11: =-510*CH11*CG11 -> -69115200 | CN11: =(((CK11*CL11/(6*CJ11^2)-(CK11/(3*CJ11))^3-CM11/(2*CJ11))^2+(-(CK11^2/(9*CJ11^2))+CL11/(3*CJ11))^3)^0.5+CK11*CL11/(6*CJ11^2)-CK11^3/(27*CJ11^3)-CM11/(2*CJ11))^(1/3)+(-(((CK11*CL11/(6*CJ11^2)-(CK11/(3*CJ11))^3-CM11/(2*CJ11))^2+(-(CK11^2/(9*CJ11^2))+CL11/(3*CJ11))^3)^0.5)+CK11*CL11/(6*CJ11^2)-CK11^3/(27*CJ11^3)-CM11/(2*CJ11))^(1/3)-CK11/(3*CJ11) -> 486.52169 | CO11: =((0.85*fc*CN11*BJ11)+(CG11*(fy-0.85*fc))-(CG11*600*((0.85*CH11)-CN11)/CN11))/1000 -> 2480.613 | CQ11: =BJ11-60 -> 140 | CR11: =BW11*1000+BJ11/2-60 -> 51.14939 | CS11: =0.85*fc*BK11/(2*CR11) -> 116.32592 | CT11: =0.85*fc*BK11*(1-CQ11/CR11) -> -20671.258 | CU11: =(600*CG11+CG11*(fy-0.85*fc)*(1-(CQ11-60)/CR11)) -> 115969.69 | CV11: =-510*CQ11*CG11 -> -21991200 | CW11: =(((CT11*CU11/(6*CS11^2)-(CT11/(3*CS11))^3-CV11/(2*CS11))^2+(-(CT11^2/(9*CS11^2))+CU11/(3*CS11))^3)^0.5+CT11*CU11/(6*CS11^2)-CT11^3/(27*CS11^3)-CV11/(2*CS11))^(1/3)+(-(((CT11*CU11/(6*CS11^2)-(CT11/(3*CS11))^3-CV11/(2*CS11))^2+(-(CT11^2/(9*CS11^2))+CU11/(3*CS11))^3)^0.5)+CT11*CU11/(6*CS11^2)-CT11^3/(27*CS11^3)-CV11/(2*CS11))^(1/3)-CT11/(3*CS11) -> 178.06482 | CX11: =((0.85*fc*CW11*BK11)+(CG11*(fy-0.85*fc))-(CG11*600*((0.85*CQ11)-CW11)/CW11))/1000 -> 2302.2998 | CZ11: =0.425*fc*BJ11 -> 2380 | DA11: =2*CZ11*(CI11-CH11) -> -1131144.4 | DB11: =CG11*(fy-0.85*fc)*(CI11-CH11+60)-CG11*fy*CI11 -> -47854662 | DC11: =(-DA11+(DA11^2-4*CZ11*DB11)^0.5)/(2*CZ11) -> 514.36192 | DD11: =600*(DC11/0.85-60)*0.85/DC11 -> 540.50882 | DE11: =IF(DD11>fy,DB11,CG11*(DD11-0.85*fc)*(CI11-CH11+60)-CG11*fy*CI11) -> -47854662 | DF11: =(-DA11+(DA11^2-4*CZ11*DE11)^0.5)/(2*CZ11) -> 514.36192 | DG11: =IF(DD11>fy,(0.85*fc*DF11*BJ11+CG11*(fy-0.85*fc)-CG11*fy),(0.85*fc*DF11*BJ11+CG11*(DD11-0.85*fc)-CG11*fy))/1000 -> 2441.0324 | DI11: =0.425*fc*BK11 -> 5950 | DJ11: =2*DI11*(CR11-CQ11) -> -1057322.3 | DK11: =CG11*(fy-0.85*fc)*(CR11-CQ11+60)-CG11*fy*CR11 -> -10137313 | DL11: =(-DJ11+(DJ11^2-4*DI11*DK11)^0.5)/(2*DI11) -> 186.82092 | DM11: =600*(DL11/0.85-60)*0.85/DC11 -> 158.43426 | DN11: =IF(DM11>fy,DK11,CG11*(DM11-0.85*fc)*(CR11-CQ11+60)-CG11*fy*CR11) -> -7813043.5 | DO11: =(-DJ11+(DJ11^2-4*DI11*DN11)^0.5)/(2*DI11) -> 184.80658 | DP11: =IF(DM11>fy,(0.85*fc*DO11*BK11+CG11*(fy-0.85*fc)-CG11*fy),(0.85*fc*DO11*BK11+CG11*(DM11-0.85*fc)-CG11*fy))/1000 -> 2111.3056 | DT11: =B11 -> C12 | DU11: =AZ11 -> 8 | DV11: =BA11 -> φ | DW11: =BB11 -> 14
A12: MIDAH | B12: C13 | C12: 41 | D12: 200 | E12: 500 | F12: 1600 | G12: 755.15 | H12: 16.11 | I12: 0 | J12: 0.29 | K12: 0 | L12: =(0.9*F12)/(0.3*E12) -> 9.6 | M12: =IF(P12>Q12,(34-12*I12/H12),(34-12*H12/I12)) -> 34 | N12: =IF(L12<=M12,"sho.col","long.col") -> sho.col | P12: =ABS(H12) -> 16.11 | Q12: =ABS(I12) -> 0 | R12: =ABS(J12) -> 0.29 | S12: =ABS(K12) -> 0 | W12: I/L | X12: 0 | AI12: 13 , 231 , 163 | AJ12: =B12 -> C13 | AL12: 200 | AM12: 500 | AN12: =AM12-60 -> 440 | AO12: =G12 -> 755.15 | AP12: =P12 -> 16.11 | AQ12: =R12 -> 0.29 | AR12: =AP12+(AQ12*AM12/AL12*((1-AS$2)/AS$2)) -> 16.500385 | AS12: =AQ12+(AP12*AL12/AM12*((1-AS$2)/AS$2)) -> 3.7598462 | AT12: =MAX(AR12:AS12) -> 16.500385 | AU12: =AT12/AO12 -> 0.021850473 | AV12: =IF(AU12<=1,"Compression","Tention") -> Compression | AW12: =IF(MAX(AP12*1000/AO12,AQ12*1000/AO12)>0.1*AM12,IF(IF(AV12="Compression",2*(0.5+AU12*10^3/(AN12-BD$2))*(-AL12*AM$2*AM12/(1.18+3*AU12*10^3*AM12/AN12^2)+AO12*10^3/AU$2)/AO$2,2*AO12*1000*(AU12*1000-0.5*AM12+0.2*AN12)/(AU$2*fy*(AN12-BD$2)))<0.01*AL12*AM12,(0.01*AL12*AM12),IF(AV12="Compression",2*(0.5+AU12*10^3/(AN12-60))*(-AL12*AM$2*AM12/(1.18+3*AU12*10^3*AM12/AN12^2)+AO12*10^3/AU$2)/AO$2,2*AO12*1000*(AU12*1000-0.5*AM12+0.2*AN12)/(AU$2*fy*(AN12-BD$2)))),MAX((AO12*1000/(0.8*AU$2)-0.85*fc*AL12*AM12)/(fy-0.85*fc),0.01*AL12*AM12)) -> 1000 | AX12: =AW12/4 -> 250 | AY12: =AW12/(AL12*AM12) -> 0.01 | AZ12: =EVEN(AW12/(PI()*BB12^2/4)) -> 8 | BA12: φ | BB12: 14 | BC12: 8.05 | BD12: =MIN(fc^0.5*AL12*AN12/(6*1000),fc^0.5*(AL12-60)*AM12/(6*1000)) -> 61.734197 | BE12: =(BC12-BF$2*BD12)/BF$2 -> -51.000864 | BF12: =FLOOR(MIN(AL12/2,MIN((3*AZ$2*BI$2/AM12),(16*AZ$2*BI$2/(fc^0.5*AM12))),(8*BB12),(24*AX$2),300),10) -> 100 | BG12: =MAX(MAX(AL12,AM12),(F12/6),450) -> 500 | BH12: =IF(BC12<0.5*BD12*BF$2,"No Need Shear Reinf.",IF(BC12<=BD12*BF$2,BF12,IF(BE12>4*BD12,"Increase b & d",FLOOR(AZ$2*BI$2*AN12/(BE12*1000),50)))) -> No Need Shear Reinf. | BI12: =IF(BH12="No Need Shear Reinf.","Use Φ"&AX$2&"@"&MIN(BF12,BH12)&"mm",IF(BH12="Increase b & d","Increase b & d","Use Φ"&AX$2&"@"&MIN(BF12,BH12)&"mm")) -> Use Φ10@100mm | BJ12: =AL12 -> 200 | BK12: =AM12 -> 500 | BL12: =0.85*(600*AN12)/(600+fy) -> 220 | BM12: =0.85*(600*(BJ12-60))/(600+fy) -> 70 | BN12: =600*(BL12/0.85-60)*0.85/BL12 -> 460.90909 | BO12: =600*(BM12/0.85-60)*0.85/BM12 -> 162.85714 | BP12: =IF(BN12>fy,(0.85*fc*BL12*BJ12+CG12*(fy-0.85*fc)-CG12*fy),(0.85*fc*BL12*BJ12+CG12*(BN12-0.85*fc)-CG12*fy))/1000 -> 1039.8696 | BQ12: =IF(BO12>fy,(0.85*fc*BM12*BK12+CG12*(fy-0.85*fc)-CG12*fy),(0.85*fc*BM12*BK12+CG12*(BO12-0.85*fc)-CG12*fy))/1000 -> 746.4696 | BR12: =IF(BN12>fy,(0.85*fc*BL12*BJ12*(BK12/2-BL12/2)+CG12*(fy-0.85*fc)*(BK12/2-60)+CG12*fy*(BK12/2-60)),(0.85*fc*BL12*BJ12*(AN12-BL12/2-60)+CG12*(BN12-0.85*fc)*(BK12/2-60)+CG12*fy*(BK12/2-60)))/1000000 -> 194.37202 | BS12: =IF(BO12>fy,(0.85*fc*BM12*BK12*((BJ12-60)-BM12/2-60)+CG12*(fy-0.85*AM$2)*(BJ12/2-60)-CG12*fy*(BJ12/2-60)),(0.85*fc*BM12*BK12*((BJ12-60)-BM12/2-60)+CG12*(BO12-0.85*fc)*(BJ12/2-60)-CG12*fy*(BJ12/2-60)))/1000000 -> 34.023784 | BT12: =BR12/BP12 -> 0.18691961 | BU12: =BS12/BQ12 -> 0.045579598 | BV12: =AP12/AO12 -> 0.02133351 | BW12: =AQ12/AO12 -> 0.00038402966 | BX12: =IF(BT12>BV12,"Compression Controls","Tension Controls") -> Compression Controls | BY12: =IF(BU12>BW12,"Compression Controls","Tension Controls") -> Compression Controls | BZ12: =IF(BX12="Compression Controls",CO12,DG12) -> 2390.4282 | CA12: =IF(BY12="Compression Controls",CX12,DP12) -> 2586.0262 | CB12: =(0.85*fc*BJ12*BK12+CG12*4*(fy-0.85*fc))/1000 -> 2868.1184 | CC12: =IF(MAX(AP12*1000/AO12,AQ12*1000/AO12)>0.1*AM12,AU$2/(1/BZ12+1/CA12-1/CB12),AU$2*0.8*CB12) -> 1491.4216 | CD12: =IF(CC12>=AO12,"Safe ","Unsafe") -> Safe | CG12: =(AZ12*0.25*22/7*BB12^2)/4 -> 308 | CH12: =BK12-60 -> 440 | CI12: =BV12*1000+BK12/2-60 -> 211.33351 | CJ12: =0.85*fc*BJ12/(2*CI12) -> 11.26182 | CK12: =0.85*fc*BJ12*(1-CH12/CI12) -> -5150.4018 | CL12: =(600*CG12+CG12*(fy-0.85*fc)*(1-(CH12-60)/CI12)) -> 87407.474 | CM12: =-510*CH12*CG12 -> -69115200 | CN12: =(((CK12*CL12/(6*CJ12^2)-(CK12/(3*CJ12))^3-CM12/(2*CJ12))^2+(-(CK12^2/(9*CJ12^2))+CL12/(3*CJ12))^3)^0.5+CK12*CL12/(6*CJ12^2)-CK12^3/(27*CJ12^3)-CM12/(2*CJ12))^(1/3)+(-(((CK12*CL12/(6*CJ12^2)-(CK12/(3*CJ12))^3-CM12/(2*CJ12))^2+(-(CK12^2/(9*CJ12^2))+CL12/(3*CJ12))^3)^0.5)+CK12*CL12/(6*CJ12^2)-CK12^3/(27*CJ12^3)-CM12/(2*CJ12))^(1/3)-CK12/(3*CJ12) -> 468.70947 | CO12: =((0.85*fc*CN12*BJ12)+(CG12*(fy-0.85*fc))-(CG12*600*((0.85*CH12)-CN12)/CN12))/1000 -> 2390.4282 | CQ12: =BJ12-60 -> 140 | CR12: =BW12*1000+BJ12/2-60 -> 40.38403 | CS12: =0.85*fc*BK12/(2*CR12) -> 147.33547 | CT12: =0.85*fc*BK12*(1-CQ12/CR12) -> -29353.932 | CU12: =(600*CG12+CG12*(fy-0.85*fc)*(1-(CQ12-60)/CR12)) -> 65091.267 | CV12: =-510*CQ12*CG12 -> -21991200 | CW12: =(((CT12*CU12/(6*CS12^2)-(CT12/(3*CS12))^3-CV12/(2*CS12))^2+(-(CT12^2/(9*CS12^2))+CU12/(3*CS12))^3)^0.5+CT12*CU12/(6*CS12^2)-CT12^3/(27*CS12^3)-CV12/(2*CS12))^(1/3)+(-(((CT12*CU12/(6*CS12^2)-(CT12/(3*CS12))^3-CV12/(2*CS12))^2+(-(CT12^2/(9*CS12^2))+CU12/(3*CS12))^3)^0.5)+CT12*CU12/(6*CS12^2)-CT12^3/(27*CS12^3)-CV12/(2*CS12))^(1/3)-CT12/(3*CS12) -> 200.73528 | CX12: =((0.85*fc*CW12*BK12)+(CG12*(fy-0.85*fc))-(CG12*600*((0.85*CQ12)-CW12)/CW12))/1000 -> 2586.0262 | CZ12: =0.425*fc*BJ12 -> 2380 | DA12: =2*CZ12*(CI12-CH12) -> -1088452.5 | DB12: =CG12*(fy-0.85*fc)*(CI12-CH12+60)-CG12*fy*CI12 -> -47920407 | DC12: =(-DA12+(DA12^2-4*CZ12*DB12)^0.5)/(2*CZ12) -> 497.78169 | DD12: =600*(DC12/0.85-60)*0.85/DC12 -> 538.52727 | DE12: =IF(DD12>fy,DB12,CG12*(DD12-0.85*fc)*(CI12-CH12+60)-CG12*fy*CI12) -> -47920407 | DF12: =(-DA12+(DA12^2-4*CZ12*DE12)^0.5)/(2*CZ12) -> 497.78169 | DG12: =IF(DD12>fy,(0.85*fc*DF12*BJ12+CG12*(fy-0.85*fc)-CG12*fy),(0.85*fc*DF12*BJ12+CG12*(DD12-0.85*fc)-CG12*fy))/1000 -> 2362.1104 | DI12: =0.425*fc*BK12 -> 5950 | DJ12: =2*DI12*(CR12-CQ12) -> -1185430 | DK12: =CG12*(fy-0.85*fc)*(CR12-CQ12+60)-CG12*fy*CR12 -> -10058399 | DL12: =(-DJ12+(DJ12^2-4*DI12*DK12)^0.5)/(2*DI12) -> 207.38345 | DM12: =600*(DL12/0.85-60)*0.85/DC12 -> 188.49642 | DN12: =IF(DM12>fy,DK12,CG12*(DM12-0.85*fc)*(CR12-CQ12+60)-CG12*fy*CR12) -> -7233657.5 | DO12: =(-DJ12+(DJ12^2-4*DI12*DN12)^0.5)/(2*DI12) -> 205.15782 | DP12: =IF(DM12>fy,(0.85*fc*DO12*BK12+CG12*(fy-0.85*fc)-CG12*fy),(0.85*fc*DO12*BK12+CG12*(DM12-0.85*fc)-CG12*fy))/1000 -> 2362.7446 | DT12: =B12 -> C13 | DU12: =AZ12 -> 8 | DV12: =BA12 -> φ | DW12: =BB12 -> 14
A13: MIDAH | B13: C14 | C13: 17 | D13: 200 | E13: 500 | F13: 1600 | G13: 489.73 | H13: 46.4 | I13: 0 | J13: 4.09 | K13: 0 | L13: =(0.9*F13)/(0.3*E13) -> 9.6 | M13: =IF(P13>Q13,(34-12*I13/H13),(34-12*H13/I13)) -> 34 | N13: =IF(L13<=M13,"sho.col","long.col") -> sho.col | P13: =ABS(H13) -> 46.4 | Q13: =ABS(I13) -> 0 | R13: =ABS(J13) -> 4.09 | S13: =ABS(K13) -> 0 | U13: C2 | V13: Top | W13: B | X13: 200 | Y13: 0 | Z13: 1000 | AA13: 1000 | AB13: 1350 | AC13: =(Z13*AA13^3/12)/AB13 -> 61728395 | AD13: =(0.7*(AC13+AC15))/(0.35*(X16+Y16)) -> 183.96884 | AE13: =MIN(MIN(1,(0.7+0.05*(AD13+AD17))),MIN(1,(0.85+0.05*MIN(AD13,AD17)))) -> 0.9 | AI13: 14 , 232 , 164 | AJ13: =B13 -> C14 | AL13: 200 | AM13: 500 | AN13: =AM13-60 -> 440 | AO13: =G13 -> 489.73 | AP13: =P13 -> 46.4 | AQ13: =R13 -> 4.09 | AR13: =AP13+(AQ13*AM13/AL13*((1-AS$2)/AS$2)) -> 51.905769 | AS13: =AQ13+(AP13*AL13/AM13*((1-AS$2)/AS$2)) -> 14.083846 | AT13: =MAX(AR13:AS13) -> 51.905769 | AU13: =AT13/AO13 -> 0.10598854 | AV13: =IF(AU13<=1,"Compression","Tention") -> Compression | AW13: =IF(MAX(AP13*1000/AO13,AQ13*1000/AO13)>0.1*AM13,IF(IF(AV13="Compression",2*(0.5+AU13*10^3/(AN13-BD$2))*(-AL13*AM$2*AM13/(1.18+3*AU13*10^3*AM13/AN13^2)+AO13*10^3/AU$2)/AO$2,2*AO13*1000*(AU13*1000-0.5*AM13+0.2*AN13)/(AU$2*fy*(AN13-BD$2)))<0.01*AL13*AM13,(0.01*AL13*AM13),IF(AV13="Compression",2*(0.5+AU13*10^3/(AN13-60))*(-AL13*AM$2*AM13/(1.18+3*AU13*10^3*AM13/AN13^2)+AO13*10^3/AU$2)/AO$2,2*AO13*1000*(AU13*1000-0.5*AM13+0.2*AN13)/(AU$2*fy*(AN13-BD$2)))),MAX((AO13*1000/(0.8*AU$2)-0.85*fc*AL13*AM13)/(fy-0.85*fc),0.01*AL13*AM13)) -> 1000 | AX13: =AW13/4 -> 250 | AY13: =AW13/(AL13*AM13) -> 0.01 | AZ13: =EVEN(AW13/(PI()*BB13^2/4)) -> 8 | BA13: φ | BB13: 14 | BC13: 23.2 | BD13: =MIN(fc^0.5*AL13*AN13/(6*1000),fc^0.5*(AL13-60)*AM13/(6*1000)) -> 61.734197 | BE13: =(BC13-BF$2*BD13)/BF$2 -> -30.800864 | BF13: =FLOOR(MIN(AL13/2,MIN((3*AZ$2*BI$2/AM13),(16*AZ$2*BI$2/(fc^0.5*AM13))),(8*BB13),(24*AX$2),300),10) -> 100 | BG13: =MAX(MAX(AL13,AM13),(F13/6),450) -> 500 | BH13: =IF(BC13<0.5*BD13*BF$2,"No Need Shear Reinf.",IF(BC13<=BD13*BF$2,BF13,IF(BE13>4*BD13,"Increase b & d",FLOOR(AZ$2*BI$2*AN13/(BE13*1000),50)))) -> 100 | BI13: =IF(BH13="No Need Shear Reinf.","Use Φ"&AX$2&"@"&MIN(BF13,BH13)&"mm",IF(BH13="Increase b & d","Increase b & d","Use Φ"&AX$2&"@"&MIN(BF13,BH13)&"mm")) -> Use Φ10@100mm | BJ13: =AL13 -> 200 | BK13: =AM13 -> 500 | BL13: =0.85*(600*AN13)/(600+fy) -> 220 | BM13: =0.85*(600*(BJ13-60))/(600+fy) -> 70 | BN13: =600*(BL13/0.85-60)*0.85/BL13 -> 460.90909 | BO13: =600*(BM13/0.85-60)*0.85/BM13 -> 162.85714 | BP13: =IF(BN13>fy,(0.85*fc*BL13*BJ13+CG13*(fy-0.85*fc)-CG13*fy),(0.85*fc*BL13*BJ13+CG13*(BN13-0.85*fc)-CG13*fy))/1000 -> 1039.8696 | BQ13: =IF(BO13>fy,(0.85*fc*BM13*BK13+CG13*(fy-0.85*fc)-CG13*fy),(0.85*fc*BM13*BK13+CG13*(BO13-0.85*fc)-CG13*fy))/1000 -> 746.4696 | BR13: =IF(BN13>fy,(0.85*fc*BL13*BJ13*(BK13/2-BL13/2)+CG13*(fy-0.85*fc)*(BK13/2-60)+CG13*fy*(BK13/2-60)),(0.85*fc*BL13*BJ13*(AN13-BL13/2-60)+CG13*(BN13-0.85*fc)*(BK13/2-60)+CG13*fy*(BK13/2-60)))/1000000 -> 194.37202 | BS13: =IF(BO13>fy,(0.85*fc*BM13*BK13*((BJ13-60)-BM13/2-60)+CG13*(fy-0.85*AM$2)*(BJ13/2-60)-CG13*fy*(BJ13/2-60)),(0.85*fc*BM13*BK13*((BJ13-60)-BM13/2-60)+CG13*(BO13-0.85*fc)*(BJ13/2-60)-CG13*fy*(BJ13/2-60)))/1000000 -> 34.023784 | BT13: =BR13/BP13 -> 0.18691961 | BU13: =BS13/BQ13 -> 0.045579598 | BV13: =AP13/AO13 -> 0.094746085 | BW13: =AQ13/AO13 -> 0.0083515406 | BX13: =IF(BT13>BV13,"Compression Controls","Tension Controls") -> Compression Controls | BY13: =IF(BU13>BW13,"Compression Controls","Tension Controls") -> Compression Controls | BZ13: =IF(BX13="Compression Controls",CO13,DG13) -> 1685.811 | CA13: =IF(BY13="Compression Controls",CX13,DP13) -> 2376.1993 | CB13: =(0.85*fc*BJ13*BK13+CG13*4*(fy-0.85*fc))/1000 -> 2868.1184 | CC13: =IF(MAX(AP13*1000/AO13,AQ13*1000/AO13)>0.1*AM13,AU$2/(1/BZ13+1/CA13-1/CB13),AU$2*0.8*CB13) -> 976.90625 | CD13: =IF(CC13>=AO13,"Safe ","Unsafe") -> Safe | CG13: =(AZ13*0.25*22/7*BB13^2)/4 -> 308 | CH13: =BK13-60 -> 440 | CI13: =BV13*1000+BK13/2-60 -> 284.74608 | CJ13: =0.85*fc*BJ13/(2*CI13) -> 8.3583239 | CK13: =0.85*fc*BJ13*(1-CH13/CI13) -> -2595.325 | CL13: =(600*CG13+CG13*(fy-0.85*fc)*(1-(CH13-60)/CI13)) -> 143978.38 | CM13: =-510*CH13*CG13 -> -69115200 | CN13: =(((CK13*CL13/(6*CJ13^2)-(CK13/(3*CJ13))^3-CM13/(2*CJ13))^2+(-(CK13^2/(9*CJ13^2))+CL13/(3*CJ13))^3)^0.5+CK13*CL13/(6*CJ13^2)-CK13^3/(27*CJ13^3)-CM13/(2*CJ13))^(1/3)+(-(((CK13*CL13/(6*CJ13^2)-(CK13/(3*CJ13))^3-CM13/(2*CJ13))^2+(-(CK13^2/(9*CJ13^2))+CL13/(3*CJ13))^3)^0.5)+CK13*CL13/(6*CJ13^2)-CK13^3/(27*CJ13^3)-CM13/(2*CJ13))^(1/3)-CK13/(3*CJ13) -> 333.27023 | CO13: =((0.85*fc*CN13*BJ13)+(CG13*(fy-0.85*fc))-(CG13*600*((0.85*CH13)-CN13)/CN13))/1000 -> 1685.811 | CQ13: =BJ13-60 -> 140 | CR13: =BW13*1000+BJ13/2-60 -> 48.351541 | CS13: =0.85*fc*BK13/(2*CR13) -> 123.05709 | CT13: =0.85*fc*BK13*(1-CQ13/CR13) -> -22555.986 | CU13: =(600*CG13+CG13*(fy-0.85*fc)*(1-(CQ13-60)/CR13)) -> 104925.63 | CV13: =-510*CQ13*CG13 -> -21991200 | CW13: =(((CT13*CU13/(6*CS13^2)-(CT13/(3*CS13))^3-CV13/(2*CS13))^2+(-(CT13^2/(9*CS13^2))+CU13/(3*CS13))^3)^0.5+CT13*CU13/(6*CS13^2)-CT13^3/(27*CS13^3)-CV13/(2*CS13))^(1/3)+(-(((CT13*CU13/(6*CS13^2)-(CT13/(3*CS13))^3-CV13/(2*CS13))^2+(-(CT13^2/(9*CS13^2))+CU13/(3*CS13))^3)^0.5)+CT13*CU13/(6*CS13^2)-CT13^3/(27*CS13^3)-CV13/(2*CS13))^(1/3)-CT13/(3*CS13) -> 183.94319 | CX13: =((0.85*fc*CW13*BK13)+(CG13*(fy-0.85*fc))-(CG13*600*((0.85*CQ13)-CW13)/CW13))/1000 -> 2376.1993 | CZ13: =0.425*fc*BJ13 -> 2380 | DA13: =2*CZ13*(CI13-CH13) -> -739008.64 | DB13: =CG13*(fy-0.85*fc)*(CI13-CH13+60)-CG13*fy*CI13 -> -48458551 | DC13: =(-DA13+(DA13^2-4*CZ13*DB13)^0.5)/(2*CZ13) -> 366.12002 | DD13: =600*(DC13/0.85-60)*0.85/DC13 -> 516.42085 | DE13: =IF(DD13>fy,DB13,CG13*(DD13-0.85*fc)*(CI13-CH13+60)-CG13*fy*CI13) -> -48458551 | DF13: =(-DA13+(DA13^2-4*CZ13*DE13)^0.5)/(2*CZ13) -> 366.12002 | DG13: =IF(DD13>fy,(0.85*fc*DF13*BJ13+CG13*(fy-0.85*fc)-CG13*fy),(0.85*fc*DF13*BJ13+CG13*(DD13-0.85*fc)-CG13*fy))/1000 -> 1735.4009 | DI13: =0.425*fc*BK13 -> 5950 | DJ13: =2*DI13*(CR13-CQ13) -> -1090616.7 | DK13: =CG13*(fy-0.85*fc)*(CR13-CQ13+60)-CG13*fy*CR13 -> -10116804 | DL13: =(-DJ13+(DJ13^2-4*DI13*DK13)^0.5)/(2*DI13) -> 192.14594 | DM13: =600*(DL13/0.85-60)*0.85/DC13 -> 231.31093 | DN13: =IF(DM13>fy,DK13,CG13*(DM13-0.85*fc)*(CR13-CQ13+60)-CG13*fy*CR13) -> -8277514.9 | DO13: =(-DJ13+(DJ13^2-4*DI13*DN13)^0.5)/(2*DI13) -> 190.59602 | DP13: =IF(DM13>fy,(0.85*fc*DO13*BK13+CG13*(fy-0.85*fc)-CG13*fy),(0.85*fc*DO13*BK13+CG13*(DM13-0.85*fc)-CG13*fy))/1000 -> 2202.646 | DT13: =B13 -> C14 | DU13: =AZ13 -> 8 | DV13: =BA13 -> φ | DW13: =BB13 -> 14
